Workbook

Sheet Matrice RISQUES (2)
L2: RISQUE
B3: 6 | C3: 12 | D3: 18 | E3: 24 | F3: 30 | G3: 36 | L3: Critique | M3: Le risque est jugé critique avec une qualité de contrôle interne non maitrisé (la situation est telle que les objectifs initiaux ne pourront vraisemblablement pas être atteints)
B4: 5 | C4: 10 | D4: 15 | E4: 20 | F4: 25 | G4: 30 | L4: Fort | M4: Le risque est jugé fort avec une qualité de contrôle interne insatisfaisant (des manquements et/ou défaillances sérieux existent qui pourraient mettre en danger le fait d’atteindre les objectifs)
B5: 4 | C5: 8 | D5: 12 | E5: 16 | F5: 20 | G5: 24 | L5: Moderé | M5: Risque jugé moderé avec une qualité de contrôle interne satisfaisante (système de contrôle interne globalement adéquat mais un certain nombre de constatations révèlent des faiblesses dans les contrôles. Ces constatations requièrent l’attention du management)
B6: 3 | C6: 6 | D6: 9 | E6: 12 | F6: 15 | G6: 18 | L6: Faible | M6: Risque jugé faible avec une qualité de contrôle interne très satisfaisant (Des possibilités d'améliorations existent, mais les faiblesses et défaillances constatées sont insignifiant)
B7: 2 | C7: 4 | D7: 6 | E7: 8 | F7: 10 | G7: 12
B8: 1 | C8: 2 | D8: 3 | E8: 4 | F8: 5 | G8: 6

Sheet Synthèse Exceptions & risqu (2
A2: N° | B2: PROCESSUS | C2: RATIO | D2: SOUS PROCESSUS | E2: Risques Majeurs | F2: gravité | G2: probabilité | H2: Risque Résiduel (Rb) | I2: Niveau de RISQUE
F3: G | G3: P | H3: est égal à GxP
A4: 1 | B4: Exploitation | C4: 0.2 | D4: Gestion clientèle (ouverture de compte, Remise chèque, Gestion opérationnelle des produits) | E4: - Identification du client (921 comptes sans Photo & 641 comptes sans signature dans le système NAFA) - Ouverture incomplète des comptes dans NAFA (531 comptes en instance d'ouverture) - Compte fermé ou à fermer (statut ''demande de cloture'') avec un solde non nul (21 comptes) - Non prelevement des frais sur les produits (Engagement par signature, ...) | F4: 4 | G4: 5 | H4: =+F4*G4 -> 20 | I4: CRITIQUE
D5: Octroi de crédit | E5: - Dossier de demande de crédit incomplet (Tous les dossiers de crédit du produit 3 en 1 établis sur la période de juin à aout étaient incomplet à la date de revue, pas de checklist des éléments composititifs du dossier, absence du plan de localisation du client, ...) - Octroi de crédit avec deblocage des fonds sans mise à disposition des fonds aux clients - Découverts non autorisés et forçage de compte (en dehors des lignes de crédits mis en place et des contrats d'avance sur chèques) - Baisse des marges d'interet (Meme Cible clientèle que les banques) | F5: 5 | G5: 5 | H5: =+F5*G5 -> 25 | I5: CRITIQUE
D6: Suivi du portefeuille | E6: - Modification de la structure initiale du crédit (rééchelonnement, restructuration, décalage d'échéance) non autorisée par les organes habilités - Non respect du niveau de Portefeuille A Risque (PAR) 0 | F6: 4 | G6: 4 | H6: =+F6*G6 -> 16 | I6: ELEVE
D7: Recouvrement | E7: Clients non correctement identifié et localisé (clients injoignables) - 243 clients injoignables | F7: 5 | G7: 5 | H7: =+F7*G7 -> 25 | I7: CRITIQUE
D8: EVALUATION EXPLOITATION | F8: =+ROUND(IFERROR(AVERAGE(F4:F7),0),0) -> 5 | G8: =+ROUND(IFERROR(AVERAGE(G4:G7),0),0) -> 5 | H8: =+F8*G8 -> 25 | I8: CRITIQUE
A9: 2 | B9: Risques crédit & suivi du portefeuille | C9: 0.2 | D9: Octroi de credit & Monitoring / Gestion du Portefeuille | E9: - Erreur d'analyse dans l'étude des dossiers des crédits (Pas de senior analyste crédit, ) - Non réalisation systématique des visites et contre-visite terrain permettant de localiser l'activité ou le domicile du client, de constater visuellement l'existence des biens présentés en garantie et d'évaluer la capacité de remboursement du client - Dossier restructuré tombé en impayé | F9: 5 | G9: 5 | H9: =+F9*G9 -> 25 | I9: CRITIQUE
D10: Gestion des impayés & Pré-Contentieux | E10: Non respect des niveaux de PAR (30, 90, 180) | F10: 5 | G10: 5 | H10: =+F10*G10 -> 25 | I10: CRITIQUE
D11: EVALUATION RISQUE & SUIVI DU PORTEFEUILLE | F11: =+ROUND(IFERROR(AVERAGE(F9:F10),0),0) -> 5 | G11: =+ROUND(IFERROR(AVERAGE(G9:G10),0),0) -> 5 | H11: =+F11*G11 -> 25 | I11: CRITIQUE
A12: 3 | B12: Système d'information | C12: 0.15 | D12: Gestion des systèmes | E12: Indisponibilité du SI et défaillances SI (dysfonctionnement) identifiées non corrigées | F12: 5 | G12: 4 | H12: =+F12*G12 -> 20 | I12: CRITIQUE
D13: Gestion des changements Système et Réseau | E13: Non respect de la procédure des changements, des configurations et des mises en production (Un changement consiste à modifier, créer ou supprimer un des composants de l'infrastructure du système d'information) | F13: 4 | G13: 3 | H13: =+F13*G13 -> 12 | I13: ELEVE
D14: Gestion des comptes et habilitations | E14: Accès non autorisé et inadéquation des accès à la fonction ou poste occupé (Profil CC peut faire des decalages) | F14: 4 | G14: 3 | H14: =+F14*G14 -> 12 | I14: ELEVE
D15: Administration des bases de données | E15: - Corruption de la base de données - Non sauvegarde des données et pas de site de secours | F15: 4 | G15: 5 | H15: =+F15*G15 -> 20 | I15: CRITIQUE
D16: EVALUATION SYSTEME D'INFORMATION | F16: =+ROUND(IFERROR(AVERAGE(F12:F15),0),0) -> 4 | G16: =+ROUND(IFERROR(AVERAGE(G12:G15),0),0) -> 4 | H16: =+F16*G16 -> 16 | I16: ELEVE
A17: 4 | B17: Opérations | C17: 0.15 | D17: Opération de caisse | E17: - Non réalisation du pointage systèmatique des tickets de caisses et de l'inventaire des espèces quotidiennement par un staff autre que le caissier lui-même. - Dépassement de la limite d'encaisse journalière autorisée - daily overnight limit - Rechargement fictif des cartes prépayées dans la plateforme - Différence de caisse | F17: 4 | G17: 4 | H17: =+F17*G17 -> 16 | I17: ELEVE
D18: Back office Opérations | E18: - Comptabilisation des remises chèques sans attendre le sort définitif du chèque par la banque - Non comptabilisation des fiches d'imputations comptables et/ou erreur d'imputation des fiches comptables, des mise en place de prets, des virements reçus et des remises chèques sur les comptes appropriés du bon montant déterminé - Non établissement des reconciliations des commissions de transferts d'argent et/ou non comptabilisation des commissions de transferts - Non établissement des états de rapprochements bancaires périodiques | F18: 4 | G18: 4 | H18: =+F18*G18 -> 16 | I18: ELEVE
D19: EVALUATION OPERATION | F19: =+ROUND(IFERROR(AVERAGE(F17:F18),0),0) -> 4 | G19: =+ROUND(IFERROR(AVERAGE(G17:G18),0),0) -> 4 | H19: =+F19*G19 -> 16 | I19: ELEVE
A20: 5 | B20: Finance & reporting | C20: 0.15 | D20: Arrêté & clôture périodique comptable | E20: - Longs suspens de plus de 90 jours sur les comptes internes et les rapprochements bancaires - Non justification des opérations comptabilisées dans le système par des pièces probantes - Déséquilibre de la balance à une date d'arrêté donnée - Absence de calcul et de comptabilisation de la réévaluation de la position de change Arrêté & clôture périodique comptable | F20: 5 | G20: 5 | H20: =+F20*G20 -> 25 | I20: CRITIQUE
D21: Reporting financier (groupe - bailleurs) / Règlementaire (Tutelle-DRS-BCEAO-COBAC-BCRG) | E21: - Sanctions règlementaires du fait du non respect systématique des normes de gestion (limitation des risques, couverture des emplois, limitation des prêts aux dirigeants, limitation des risques par signature, coefficient de liquidité, constitution de la réserve générale, capitalisation,....) du dispositif prudentiel instaurées par l'Institution - Non automatisation des reporting reglementaire, financier et métier | F21: 4 | G21: 2 | H21: =+F21*G21 -> 8 | I21: MODERE
D22: Fiscalité | E22: - Absence ou retard de déclaration/paiement des impots, taxes et redevances et/ou erreur de calcul dans la détermination des impots, taxes et redevances à payer - Redressement fiscal et social | F22: 4 | G22: 3 | H22: =+F22*G22 -> 12 | I22: ELEVE
D23: Trésorerie / ALM | E23: Risque de liquidité, de taux d'intéret et de taux de change et respect des ratios reglementaires | F23: 5 | G23: 3 | H23: =+F23*G23 -> 15 | I23: ELEVE
D24: EVALUATION FINANCE & REPORTING | F24: =+ROUND(IFERROR(AVERAGE(F20:F23),0),0) -> 5 | G24: =+ROUND(IFERROR(AVERAGE(G20:G23),0),0) -> 3 | H24: =+F24*G24 -> 15 | I24: ELEVE
A25: 6 | B25: Gouvernance & Contrôle interne (Gouv & CI) | C25: 0.05 | D25: Gouvernance | E25: - Non respecte des dispositions légales et Réglementaires relatives à la gouvernance (Respect de la loi sur les microfinances, des instructions, des statuts) - Conformité des statuts avec la législation - Bon fonctionnement des organes d'administration et de direction et de contrôle | F25: 4 | G25: 4 | H25: =+F25*G25 -> 16 | I25: ELEVE
D26: Contrôle interne | E26: - Existance, accessibilité et Connaissance des politiques et procédures écrites en vigueur - Bonne séparation des taches (maker & checker) - Réalisation systématique des contrôle de premier niveau - Politique de lutte antiblanchiment - Mise en place et fonctionnement d'un comité d'audit - Cartographie des risques (identification et cotation des risques inhérents, évaluation du contrôle interne, cotation des risques résiduels) | F26: 4 | G26: 4 | H26: =+F26*G26 -> 16 | I26: ELEVE
D27: EVALUATION CI & GOUVERNANCE | F27: =+ROUND(IFERROR(AVERAGE(F25:F26),0),0) -> 4 | G27: =+ROUND(IFERROR(AVERAGE(G25:G26),0),0) -> 4 | H27: =+F27*G27 -> 16 | I27: ELEVE
A28: 7 | B28: Juridique & contentieux | C28: 0.05 | D28: Gestion du Contentieux | E28: Non utisation de tous les recours contentieux et Pilotage, suivi inapproprié de la performance reporting Recouvrement en raison d'une absence de tableaux de bord et d'indicateurs dédiés au suivi formel du recouvrement | F28: 3 | G28: 3 | H28: =+F28*G28 -> 9 | I28: MODERE
D29: Gestion des contrats et Etudes juridiques | E29: Modification abusive ou non autorisée des contrats de crédit par les entités opérationnelles et/ou contrat non établi ou vérifié par le juridique | F29: 5 | G29: 2 | H29: =+F29*G29 -> 10 | I29: MODERE
D30: Gestion des garanties | E30: Impossibilité d'exécuter la garantie entièrement en cas de besoin : Non mise à jour des valeurs des garanties en raison d'une détérioration normale et/ou de sinistre impactant de manière significative la valeur de l'actif (incendie, dégât des eaux, etc.), mauvaise localisation du bien garanti, immeubles construits sur des titres précaires, perte d'emploi pour des particuliers salariés, garantie pris sur des actifs non éligibles par la règlementation | F30: 3 | G30: 2 | H30: =+F30*G30 -> 6 | I30: MODERE
D31: Gestion des Avis à Tiers Détenteur ou ATD, des saisies attributions et saisies conservatoires | E31: Traitement inapproprié ou hors délai des Avis à Tiers Détenteur ou ATD, des saisies attributions et saisies conservatoires | F31: 3 | G31: 2 | H31: =+F31*G31 -> 6 | I31: MODERE
D32: EVALUATION JURIDIQUE & CONTENTIEUX | F32: =+ROUND(IFERROR(AVERAGE(F28:F31),0),0) -> 4 | G32: =+ROUND(IFERROR(AVERAGE(G28:G31),0),0) -> 2 | H32: =+F32*G32 -> 8 | I32: MODERE
A33: 8 | B33: Ressources Humaines | C33: 0.025 | D33: Gestion administrative du personnel & Affaires sociales | E33: - Dossier du personnel incomplet - Non respect des obligations légales en matière de santé et sécurité au travail et des engagements de l’organisation | F33: 4 | G33: 3 | H33: =+F33*G33 -> 12 | I33: ELEVE
D34: Politique de rémunération et Paie | E34: - Non-conformité règlementaire des traitements salariaux - Non justification des variations de la masse salariale (modifications frauduleuses des données de la paie, Erreur de calcul ou d'imputation des salaires, écart sur paiement des salaires) - Non détermination des provisions pour congé et retraite et/ou non comptabilisations des provisions pour congé et retraite - Absence de déclarations fiscales et sociales et/ou erreur dans les déclarations fiscales et sociales liées à la paie - Absence d'un outil de gestion de la paie | F34: 4 | G34: 3 | H34: =+F34*G34 -> 12 | I34: ELEVE
D35: Appréciation des performance - Evaluation | E35: - Non respect du processus d'évaluation - Non évaluation des staffs et/ou Critères d’évaluation non définis ou non adéquats - Evaluation non objective | F35: 3 | G35: 4 | H35: =+F35*G35 -> 12 | I35: ELEVE
D36: EVALUATION RH | F36: =+ROUND(IFERROR(AVERAGE(F33:F35),0),0) -> 4 | G36: =+ROUND(IFERROR(AVERAGE(G33:G35),0),0) -> 3 | H36: =+F36*G36 -> 12 | I36: ELEVE
A37: 9 | B37: Administration, Achats & Logistique | C37: 0.025 | D37: Planification & Administration des achats | E37: - Non respect de la politique d'achat - Réalisation de dépenses non-autorisées - Absence ou Pertes de pièces jusificatives des achats (Non justification des achats) | F37: 3 | G37: 3 | H37: =+F37*G37 -> 9 | I37: MODERE
D38: Logistique & moyens généraux | E38: - Perte / vol / et dégradation du patrimoine immobilier, mobilier et consommables - Inadequation des systèmes de sécurité incendie et absence de plan d'évacuation des locaux | F38: 3 | G38: 3 | H38: =+F38*G38 -> 9 | I38: MODERE
D39: Gestion administrative | E39: Perte de valeurs et de courriers due à une conservation ou un mode d'acheminement ou un traitement inapproprié | F39: 3 | G39: 3 | H39: =+F39*G39 -> 9 | I39: MODERE
D40: EVALUATION ACHAT LOGISTIQUE | F40: =+ROUND(IFERROR(AVERAGE(F37:F39),0),0) -> 3 | G40: =+ROUND(IFERROR(AVERAGE(G37:G39),0),0) -> 3 | H40: =+F40*G40 -> 9 | I40: MODERE
C42: =+SUM(C4:C40) -> 1 | D42: EVALUATION GLOBALE - NOTE FINALE | F42: =ROUND(+F8*$C4+F11*$C9+F24*$C20+F16*$C12+F19*$C17+F40*$C37+F36*$C33+F32*$C28+F27*$C25,0) -> 5 | G42: =ROUND(+G8*$C4+G11*$C9+G24*$C20+G16*$C12+G19*$C17+G40*$C37+G36*$C33+G32*$C28+G27*$C25,0) -> 4 | H42: =+G42*F42 -> 20 | I42: CRITIQUE
...

Sheet DASHBOARD

Sheet HOME

Sheet Définition & Objectifs

Sheet Préambule

Sheet Principes
B2: PRINCIPES | C2: ENONCE DU PRINCIPE | D2: EXPLICATIONS
B3: Principe 1 | C3: Objectivité et rationnalité de l'évaluation des risques | D3: Un exercice de cette nature expose naturellement les acteurs à un risque d'erreur de jugement ou d'appréciation sur l'analyse du risque. Ce biais peut être lié à des facteurs personnels ou psychologiques (syndrome "alarmiste" ou "paranoïaque") ou à un élément de l'environnement interne ("conflits internes et considérations crypto-personnelles"). Les fiches d'évaluation prévoient un champ "Commentaires" permettant à l'évaluateur (ou groupe d'évaluateurs) de justifier ses évaluations jugées extrêmes (entre 5 et 6).
B4: Principe 2 | C4: Objectif de l'évaluation (évaluation du risque inhérent ou risque brut et de la maturité des contrôles) | D4: Dans le cadre de cet atelier, il vous est demandé de procéder d'une part à l'évaluation des risques inhérents (risques bruts) c'est-à-dire de faire fi des dispositifs de contrôle en vigueur. L'évaluation du risque inhérent permet d'appréhender de manière globale l'exposition de la filiale sur les différents process cible.
B5: Principe 3 | C5: Principe de corrélation de l'évaluation des risques avec les objectifs stratégiques et opérationnels | D5: Il est demandé à chaque évaluateur de procéder à cette exercice en corrélation avec les objectifs opérationnels de ses processus ou sous processus
B6: Principe 4 | C6: Probabilité du risque est différente de la fréquence de survenance de l'incident | D6: Un risque jamais survenu peut présenter une probabilité de survenance élevée et vice-versa. L'évaluateur devra donc avoir à l'esprit que les facteurs rendant possibles la survenance du risque.
B7: Principe 5 | C7: Evaluation de la gravité | D7: L’appréciation de la gravité est une estimation très fine des impacts supposés de la survenance du risque sur la réalisation des objectifs de l’organisation. Il conviendra de ne pas surestimer des risques dont les impacts ne seraient que « locaux ». De même, il faudra veiller à ne pas sous estimer des risques dont l'impact est plus général. L'exercice d'évaluation requiert un élargissement de la perspective au-delà de votre simple domaine (direction, cellule, process, activité).

Sheet Echelle P & G
A1: CRITERE DE QUANTIFICATION DE LA PROBABILITE D'OCCURRENCE ET DE L'IMPACT DU RISQUE OPERATIONNEL
A2: Gravité | B2: Qualification de l'échelle | C2: Explication de l'échelle de gravité
A3: 1 | B3: Inoffensif (aucun impact) | C3: Ne présente aucune forme d'impact sur l'activité ou les objectifs
A4: 2 | B4: Faible impact | C4: Un niveau d'impact sur les activités ou les objectifs stratégiques ou opérationnels est perceptible mais ne gêne pas le déroulement des opérations
A5: 3 | B5: Impact sérieux sur process secondaires | C5: Des niveaux d'impact circonscris à des processus (importants mais non critiques ont été notés. Il s'agit de processus non liés directement à la qualité de service
A6: 4 | B6: Impact sérieux sur process métiers | C6: Il s'agit soit de processus critiques fortement impactées et de manière durable. soit de désagréments perceptibles en interne ou par le membre sur des processus liés directement à la qualité de service
A7: 5 | B7: Fort impact (généralisé) | C7: Niveau de risque impactant de manière significative et durable l'ensemble des activités du l'entité ainsi que ses objectifs stratégiques et opérationnels
A8: 6 | B8: Crise majeure / Arrêt de l'exploitation | C8: Niveau de risque impactant de manière absolue et durable la continuité de l'activité et autres processus critiques de l'entité
A11: Probabilité | B11: Qualification de l'échelle | C11: Explication de l'échelle de probabilité
A12: 1 | B12: Quasi impossible | C12: Ce niveau de l'échelle correspond au risque pour lesquels aucun facteur indiquant une possible survenance n'a été identifiée ni au niveau interne, ni externe
A13: 2 | B13: Eventuelle / possible | C13: Le risque est plausible et, un ou des facteurs internes ou externes le rendent tout à fait réalisable
A14: 3 | B14: Vraisemblable | C14: Plusieurs facteurs précis ont été identifiés au niveau interne ou externe favorisant la survenance du risque. Par exemple, une vague de démissions au niveau du support informatique doublée ou non d'une augmentation exponentielle du nombre de sollicitations par les membres rendra assez probable le risque de dégradation de la qualité du support (qualité des traitements, délai de résolution des problèmes, etc.)
A15: 4 | B15: Probable | C15: Un nombre important de facteurs potentiels ont été identifiés au niveau interne ou externe favorisant la survenance du risque. Par exemple, une vague de démissions au niveau du support informatique + une augmentation exponentielle du nombre de sollicitations par les services + dégradation des outils de traitement + démotivation + etc. rendra extrêmement probable le risque de dégradation de la qualité du support (qualité des interventions, délai de résolution des problèmes, etc.). Les facteurs indiquent une survenance qui pourrait être différée.
A16: 5 | B16: Hautement probable | C16: Ce niveau de risque correspond à l'identification de plusieurs signes confirmés qui indiquent une survenance probable et imminente
A17: 6 | B17: Evènement certain | C17: Aucun doute sur la survenance du risque. Tout indique que le risque se réalisera de manière certaine. Toutes les conditions sont réunies pour que le risque survienne à tout moment.

Sheet Echelle de contrôle
B3: Niveau de l'échelle | C3: Qualification de l'échelle | D3: Explicitation de l'échelle | E3: Maturité du contrôle
B4: 1 | C4: Initial | D4: Dispositif de contrôle jugé "embryonnaire" | E4: Inexistant
B5: 2 | C5: Aléatoire | D5: Pratique de contrôle identifié mais présentant un caractère aléatoire et fortement conditionné par la disponibilité et la volonté de certaines individualités (prépondérance du facteur humain) | E5: Informel
B6: 3 | C6: Opérationnel | D6: Contrôle opérationnel et mis en œuvre manuellement ou de manière semi-automatique, conceptuellement satisfaisant mais ne présentant aucune garantie de mise en œuvre | E6: Opérationnel
B7: 4 | C7: Standardisé | D7: Dispositf de contrôle indépendant du facteur humain, testé périodiquement avec des résultats globalement concluants et un système d'archivage des preuves assurant une parfaite traçabilité des tests | E7: Standardisé
B8: 5 | C8: Optimisé | D8: Contrôle paramétré de manière automatique ne nécessitant pas d'intervention humaine. Un contrôle des paramètres est néanmoins effectué suivant une périodicité définie (contrôles de type applicatif ou "embarqué" par un SI) | E8: Optimisé

Sheet Matrice RISQUES
L2: Lexique
B3: 6 | C3: 12 | D3: 18 | E3: 24 | F3: 30 | G3: 36 | L3: Critique | M3: Le risque est jugé critique (la situation est tellement grave que l'organisation est face à la faillite ou à une dégradation accrue de sa réputation ou image)
B4: 5 | C4: 10 | D4: 15 | E4: 20 | F4: 25 | G4: 30 | L4: Très Elevé | M4: Le risque est jugé très élevé (des fraudes sérieuses existent telles que les objectifs initiaux ne pourront vraisemblablement pas être atteints)
B5: 4 | C5: 8 | D5: 12 | E5: 16 | F5: 20 | G5: 24 | L5: Elevé | M5: Le risque est jugé élevé (des manquements et/ou défaillances sérieux existent qui pourraient mettre en danger le fait d’atteindre les objectifs)
B6: 3 | C6: 6 | D6: 9 | E6: 12 | F6: 15 | G6: 18 | L6: Moderé | M6: Risque jugé moderé (un certain nombre de constatations révèlent des faiblesses dans les contrôles. Ces constatations requièrent l’attention du management)
B7: 2 | C7: 4 | D7: 6 | E7: 8 | F7: 10 | G7: 12 | L7: Faible | M7: Risque jugé faible (Des possibilités d'améliorations existent, mais les faiblesses et défaillances constatées sont insignifiants)
B8: 1 | C8: 2 | D8: 3 | E8: 4 | F8: 5 | G8: 6 | L8: Non significatif | M8: Risque jugé insignifiant par rapport aux process métier

Sheet Constats Détaillés
A2: N° | B2: PROCESSUS | C2: RATIO | D2: SOUS PROCESSUS | E2: RISQUES | F2: gravité | G2: probabilité | H2: Risque Résiduel (Rb)
F3: G | G3: P | H3: est égal à GxP
A4: 1 | B4: Exploitation | C4: 0.25 | D4: Gestion clientèle (ouverture de compte, Remise chèque, Gestion opérationnelle des produits) | E4: Dossier d'ouverture de compte clientèle incomplet et/ou mauvaise identification du client | H4: =+F4*G4 -> 0
E5: Absence des signatures et photos scannées des clients dans le système NAFA | H5: =+F5*G5 -> 0
E6: Mauvaise gestion opérationnelle des produits (Non prelevement de frais, non traitement des requetes clients) | H6: =+F6*G6 -> 0
D7: Octroi de crédit | E7: Dossier de demande de crédit incomplèt et/ou contenant des pièces non authentiques | H7: =+F7*G7 -> 0
E8: Non respect des limites des comités de crédits et des seniors credit officers | H8: =+F8*G8 -> 0
E9: Mauvaise évaluation de la capacité de remboursement (capacité financière) du client et/ou mauvaise identification du besoin du client | H9: =+F9*G9 -> 0
E10: Découverts non autorisés et forçage de comptes | H10: =+F10*G10 -> 0
D11: Suivi du portefeuille | E11: Non évaluation du portefeuille à risque (PAR) et/ou évaluation erronée à travers une sous estimation du PAR | H11: =+F11*G11 -> 0
E12: Modification de la structure initiale du crédit (Rééchelonnement, restructuration, décalage d'échéance) non autorisée par les organes habilétés | H12: =+F12*G12 -> 0
D13: Recouvrement | E13: Clients non correctement identifié et localisé (clients injoignables) | H13: =+F13*G13 -> 0
E14: Détournement des recouvrements de créances par les agents en charge du recouvrement | H14: =+F14*G14 -> 0
D15: EVALUATION EXPLOITATION | F15: =+ROUND(IFERROR(AVERAGE(F4:F14),0),0) -> 0 | G15: =+ROUND(IFERROR(AVERAGE(G4:G14),0),0) -> 0 | H15: =+F15*G15 -> 0
A16: 2 | B16: Risques & suivi du portefeuille | C16: 0.2 | D16: Monitoring / Gestion du Portefeuille | E16: Risque de contrepartie due à la méconnaissance de la situation globale du client par les analystes risques (total des engagements, cautions, absence d'analyse sectorielle, situation financière du client, etc.) | H16: =+F16*G16 -> 0
D17: Monitoring / Gestion du Portefeuille | E17: Dossier restructuré tombé en impayé | H17: =+F17*G17 -> 0
D18: Gestion des impayés & Pré-Contentieux | E18: Non respect des niveaux de PAR (30, 90, 180) | H18: =+F18*G18 -> 0
D19: EVALUATION RISQUE & SUIVI DU PORTEFEUILLE | F19: =+ROUND(IFERROR(AVERAGE(F16:F18),0),0) -> 0 | G19: =+ROUND(IFERROR(AVERAGE(G16:G18),0),0) -> 0 | H19: =+F19*G19 -> 0
A20: 4 | B20: Finance & reporting | C20: 0.15 | D20: Contrôle de gestion | E20: Non justification des écarts budgétaires et/ou mauvaise analyse desdits écarts - les entités opérationnelles (directions, services, agence et siège) ne procèdent pas à des analyses de fond mais s'inscrivent plus dans une logique de justification sans entrer dans une dynamique de plans d'actions correctifs. La non mise en œuvre des actions arrêtées en M-1 ne sont pas expliquées. | H20: =+F20*G20 -> 0
D21: Arrêté & clôture comptable | E21: Non justification des soldes des comptes internes (y compris soldes bancaires) à une date d'arrêté donnée (Non établissement des proofs et/ou proofs mal établis ou proofs présentant des écarts de rapprochement non justifiés) | H21: =+F21*G21 -> 0
D22: Arrêté & clôture comptable | E22: Longs suspens de plus de 90 jours sur les comptes internes et les rapprochements bancaires | H22: =+F22*G22 -> 0
D23: Arrêté & clôture comptable | E23: Non justification des opérations comptabilisées dans le système par des pièces probantes | H23: =+F23*G23 -> 0
D24: Arrêté & clôture comptable | E24: Déséquilibre de la balance à une date d'arrêté donnée | H24: =+F24*G24 -> 0
D25: Arrêté & clôture comptable | E25: Absence de calcul et de comptabilisation de la réévaluation de la position de change à la date de clôture | H25: =+F25*G25 -> 0
D26: Reporting financier (groupe - bailleurs) / Règlementaire (Tutelle-DRS-BCEAO-COBAC-BCRG) | E26: Sanctions règlementaires du fait du non respect systématique des normes de gestion (limitation des risques, couverture des emplois, limitation des prêts aux dirigeants, limitation des risques par signature, coefficient de liquidité, constitution de la réserve générale, capitalisation,....) du dispositif prudentiel instaurées par l'Institution | H26: =+F26*G26 -> 0
D27: Fiscalité | E27: Absence ou retard de déclaration/paiement des impots, taxes et redevances et/ou erreur de calcul dans la détermination des impots, taxes et redevances à payer | H27: =+F27*G27 -> 0
D28: Trésorerie / ALM | E28: Risque de liquidité de taux et de change et respect des ratios reglementaires | H28: =+F28*G28 -> 0
D29: EVALUATION FINANCE & REPORTING | F29: =+ROUND(IFERROR(AVERAGE(F20:F28),0),0) -> 0 | G29: =+ROUND(IFERROR(AVERAGE(G20:G28),0),0) -> 0 | H29: =+F29*G29 -> 0
A30: 3 | B30: Système d'information | C30: 0.1 | D30: Gestion des systèmes | E30: Indisponibilité du SI et défaillances SI (dysfonctionnement) identifiées non corrigées | H30: =+F30*G30 -> 0
D31: Gestion des changements Système et Réseau | E31: Non respect de la procédure des changements, des configurations et des mises en production (Un changement consiste à modifier, créer ou supprimer un des composants de l'infrastructure du système d'information) | H31: =+F31*G31 -> 0
D32: Gestion des comptes et habilitations | E32: Accès non autorisé et inadéquation des accès à la fonction ou poste occupé | H32: =+F32*G32 -> 0
D33: Gestion du parc & Maintenance physique et système | E33: Absence d'inventaire physique périodique du parc informatique et de maintenance dudit parc | H33: =+F33*G33 -> 0
D34: Administration des bases de données | E34: Risque de perte de données d'exploitation liée à la non sauvegarde des données et pas de site de secours | H34: =+F34*G34 -> 0
E35: Risque de corruption de la base de données | H35: =+F35*G35 -> 0
E36: Risque de non fonctionnement des serveurs de base de données tant au niveau de la conception des bases, des tests de validation, de la coordination des intervenants, de l'exploitation, de la protection et du contrôle d'utilisation | H36: =+F36*G36 -> 0
D37: Sécurité logique et accès physiques des systèmes d'information | E37: Les utilisateurs non identifiés peuvent faire des changements non autorisés dans les programmes et les données | H37: =+F37*G37 -> 0
E38: Transactions non autorisées par les utilisateurs dont l’accès n’a pas été authentifié | H38: =+F38*G38 -> 0
D39: Gestion des incidents | E39: Diagnostic des incidents non réalisé ou réalisé tardivement et Clôture d'un incident non résolu | H39: =+F39*G39 -> 0
D40: EVALUATION SYSTEME D'INFORMATION | F40: =+ROUND(IFERROR(AVERAGE(F30:F39),0),0) -> 0 | G40: =+ROUND(IFERROR(AVERAGE(G30:G39),0),0) -> 0 | H40: =+F40*G40 -> 0
A41: 5 | B41: Opérations | C41: 0.1 | D41: Opération de caisse | E41: Non réalisation du pointage systèmatique des tickets de caisses et de l'inventaire des espèces quotidiennement par un staff autre que le caissier lui-même. | H41: =+F41*G41 -> 0
...

Sheet DMCC
A1: ANALYSE DES RISQUES OPERATIONNELS - MARKETING & PRODUITS
A2: N° | B2: PROCESSUS | C2: RATIO | D2: SOUS PROCESSUS | E2: EXCEPTIONS MAJEURES CONSTATEES | F2: RISQUES CORRELES | G2: FAMILLE DU RISQUE | H2: Gravité | I2: Probabilité | J2: Risque brut (Rb) | K2: Justification de l'évaluation en cas de risque jugé critique | L2: DISPOSITIF DE PREVENTION ET DE CONTRÔLE | P2: Gravité résiduelle | Q2: Probabilité résiduelle | R2: Risque résiduel (Rr)
H4: G | I4: P | J4: est égal à GxP | L4: Description du dispositif à mettre en œuvre | M4: Dispositif existant ou Non | N4: Owner du Contrôle | O4: Efficacité du dispositif | P4: G | Q4: Pr | R4: est égal à GxP
A5: 1 | B5: MARKETING PRODUITS | C5: 0.025 | D5: Gestion clientèle | E5: • Absence de plan d'action commerciale et stratégique pour le développement des produits de COFINA | F5: Risque lié à la mission commerciale Risque de concurrence | G5: Risque stratégique | H5: 4 | I5: 2 | J5: =H5*I5 -> 8 | L5: Mise en placed d' un plan action annuel avec des revue d'étape | M5: OUI | N5: DEX | O5: 2 | P5: =H5 -> 4 | Q5: =I5/O5 -> 1 | R5: =P5*Q5 -> 4
E6: Absence de suivi sur la gestion des réclamations clients | F6: Risque lié à la mission commerciale Risque opérationnel Risque de non-conformité | G6: Risque stratégique | H6: 3 | I6: 3 | J6: =H6*I6 -> 9 | L6: Existence d'un disposirtif de suivi des réclamations | M6: OUI | N6: R.MCC | O6: 2 | P6: =H6 -> 3 | Q6: =I6/O6 -> 1.5 | R6: =P6*Q6 -> 4.5
E7: Dysfonctionnement/obsolescence des enseignes et totems | F7: Risque d'image | G7: Risque stratégique | H7: 4 | I7: 3 | J7: =H7*I7 -> 12 | L7: En plus des remontées des chefs d'agence des revues semestrielle sont faites | M7: OUI | N7: R.MCC | O7: 2 | P7: =H7 -> 4 | Q7: =I7/O7 -> 1.5 | R7: =P7*Q7 -> 6
E8: Non-affichage des conditions générales à jour dans les agences | F8: Risque de non-conformité réglementaire | G8: Risque réglementaire | H8: 3 | I8: 2 | J8: =H8*I8 -> 6 | L8: Revue semestriel sur l'affichage des conditions générales | M8: OUI | N8: R.MCC/Chef d'agence | O8: 2 | P8: =H8 -> 3 | Q8: =I8/O8 -> 1 | R8: =P8*Q8 -> 3
E9: • Défaut constatée sur la qualité de service délivrée en Agence | F9: Risque lié à la mission commerciale | G9: Risque stratégique | H9: 4 | I9: 3 | J9: =H9*I9 -> 12 | L9: Mise en plance d'un planning annuel de formation de remise à niveau | M9: OUI | N9: DEX/R.MCC/Chef d'agence | O9: 2 | P9: =H9 -> 4 | Q9: =I9/O9 -> 1.5 | R9: =P9*Q9 -> 6
D10: Gestion des produits | E10: • Défaut de communication des produits | F10: Risque lié à la mission sociale | G10: Risque stratégique | H10: 3 | I10: 3 | J10: =H10*I10 -> 9 | L10: Existence d'un plannig de formation sur 2026 | M10: OUI | N10: RMCC | O10: 2 | P10: =H10 -> 3 | Q10: =I10/O10 -> 1.5 | R10: =P10*Q10 -> 4.5
E11: Absence de mise à jour des conditions générales conformément aux pratiques | F11: Risque de non-conformité | G11: Risque opérationnel | H11: 4 | I11: 2 | J11: =H11*I11 -> 8 | L11: Mise a jour systématique à chaque modification | M11: OUI | N11: RMCC | O11: 2 | P11: =H11 -> 4 | Q11: =I11/O11 -> 1 | R11: =P11*Q11 -> 4
E12: Non réalisation d'une étude de marché préalable à la création d'un nouveau produit/service et nécessaire à la compréhension du besoin identifié et l’identification des pistes et options des solutions | F12: Risque de perte financière Risque lié à la mission commerciale | G12: Risque stratégique | H12: 4 | I12: 3 | J12: =H12*I12 -> 12 | L12: Réaliser une étude de marché avant toute mise en place d'un nouveau produit/service | M12: NON | N12: DEX/R.MCC | O12: 1 | P12: 4
E13: Absence de fiche de produit validée pour une nouvelle offre de produit/service | F13: Risque opérationnel | G13: Risque opérationnel | H13: 4 | I13: 2 | J13: =H13*I13 -> 8 | L13: Existence d'un dispositif encadré par une politique de lancement de nouveau produit | M13: OUI | N13: DEX/R.MCC | O13: 3 | P13: 4
E14: Absence de formation des utilisateurs (INTERNES)d'un nouveau produit/service | F14: Risque de fraude Risque opérationnel | G14: Risque opérationnel | H14: 4 | I14: 3 | J14: =H14*I14 -> 12 | M14: NON | N14: DEX/R.MCC | O14: 2 | P14: 4
E15: Absence de Protection de la proprièté intellectuelle | F15: Risque d'image Risque de litiges | G15: Risque stratégique | H15: 4 | I15: 2 | J15: =H15*I15 -> 8 | L15: Protéger les noms des produits et les enregistrer à l'OAPI | N15: RMCC | O15: 2 | P15: =H15 -> 4 | Q15: =I15/O15 -> 1 | R15: =P15*Q15 -> 4
E16: Absence de contrôle de conformité ou validation lors du lancement d'un nouveau produit | F16: Risque de non-conformité Risque opérationnel | G16: Risque opérationnel | H16: 4 | I16: 2 | J16: =H16*I16 -> 8 | L16: Validation systématique de la conformié | M16: NON | N16: RMCC | O16: 2 | P16: =H16 -> 4 | Q16: =I16/O16 -> 1 | R16: =P16*Q16 -> 4
D17: Evénements & Relations avec les tiers | E17: Non-Conformité relative aux prises de parole publique. | F17: Risque d'image Risque de réputation | G17: Risque stratégique | H17: 4 | I17: 2 | J17: =H17*I17 -> 8 | L17: Procedure encadrant la prise de parole | M17: OUI | N17: RMCC | O17: 2 | P17: =H17 -> 4 | Q17: =I17/O17 -> 1 | R17: =P17*Q17 -> 4
E18: Absence de validation par les personnes habilitées d'une création graphique | F18: Risque de perte financière Risque lié à la mission commerciale | G18: Risque stratégique | H18: 3 | I18: 3 | J18: 9 | L18: Procedure encadrant la prise de parole | M18: OUI | N18: MCC | O18: 2 | P18: 3
E19: Mauvaise gestion des supports de communication et matériels promotionnels | F19: Risque de perte, vols, dégradation | G19: Risque opérationnel | H19: 3 | I19: 2 | J19: 6 | L19: Faire un suivi adéquat des supports de communication et matériels promotionnels | M19: OUI | N19: MCC | O19: 3 | P19: 3
E20: Absence de politique en matière RSE | F20: Risque d'image, Risque de non-conformité | G20: Risque stratégique | H20: 4 | I20: 3 | J20: 12 | L20: Existence d'une politique de formation | M20: NON | N20: DEX/R.MCC | O20: 1 | P20: 4
D21: Organisation d'événements d'entreprise | E21: Non respect des Processs événementiels (dépassement budget, benchmarking inexistant, proposition non autorisée…) | F21: Risque d'image, Perte financière | G21: Risque stratégique | H21: 4 | I21: 2 | J21: =H21*I21 -> 8 | L21: Mise en place d'un système de mémo avec validation dela direction générale et finance | N21: RMCC | O21: 2 | P21: =H21 -> 4 | Q21: =I21/O21 -> 1 | R21: =P21*Q21 -> 4
D22: Respect de la réglementation relative à la communication | E22: Non Respect du droit d'auteur | F22: Risque d'image, Risque de non-conformité | G22: Risque stratégique | H22: 3 | I22: 2 | J22: =H22*I22 -> 6 | L22: Existence d'une fiche de cesssion de droit d'image | N22: RMCC | O22: 2 | P22: =H22 -> 3 | Q22: =I22/O22 -> 1 | R22: =P22*Q22 -> 3
A23: MARKETING & PRODUITS | E23: EVALUATION INTRINSEQUE | H23: =+ROUND(IFERROR(AVERAGE(H5:H22),0),0) -> 4 | I23: =+ROUND(IFERROR(AVERAGE(I5:I22),0),0) -> 2 | J23: =H23*I23 -> 8 | L23: EVALUATION RESIDUELLE | O23: =+ROUND(IFERROR(AVERAGE(O5:O22),0),0) -> 2 | P23: =+ROUND(IFERROR(AVERAGE(P5:P22),0),0) -> 4 | Q23: =+ROUND(IFERROR(AVERAGE(Q5:Q22),0),0) -> 1 | R23: =+ROUND(IFERROR(AVERAGE(R5:R11),0),0) -> 5
F25: Risque de Fraude | G25: =COUNTIF(G5:G22,F25) -> 0
F26: Risque opérationnel | G26: =COUNTIF(G5:G22,F26) -> 5
F27: Risque stratégique | G27: =COUNTIF(G5:G22,F27) -> 12
F28: Risque de crédit | G28: =COUNTIF(G5:G22,F28) -> 0
F29: Risque réglementaire | G29: =COUNTIF(G5:G22,F29) -> 1
F30: Risque de liquidité | G30: =COUNTIF(G5:G22,F30) -> 0
F31: Risque exogéne | G31: =COUNTIF(G5:G22,F31) -> 0

Sheet AGENCES
A1: ANALYSE DES RISQUES OPERATIONNELS - DIRECTION EXPLOITATION
A2: N° | B2: PROCESSUS | C2: RATIO | D2: SOUS PROCESSUS | E2: EXCEPTIONS MAJEURES CONSTATEES | F2: RISQUES CORRELES | G2: FAMILLE DE RISQUE | H2: Gravité | I2: Probabilité | J2: Risque brut (Rb) | K2: Justification de l'évaluation en cas de risque jugé critique | L2: DISPOSITIF DE PREVENTION ET DE CONTRÔLE | P2: Gravité résiduelle | Q2: Probabilité résiduelle | R2: Risque résiduel (Rr)
H4: G | I4: P | J4: est égal à GxP | L4: Description du dispositif | M4: Dispositif existant ou Non | N4: Owner du Contrôle | O4: Efficacité du dispositif | P4: G | Q4: Pr | R4: est égal à GxP
B5: AGENCES | C5: 0.1 | D5: Gestion clientèle (ouverture de compte, Gestion opérationnelle des produits) | E5: • Identification du client (comptes sans Photo & comptes sans signature dans le système FLEXCUB) | F5: Risque opérationnel Risque de non-conformité | G5: Risque opérationnel | H5: 4 | I5: 3 | J5: =H5*I5 -> 12 | L5: Ne pas procéder à l'ouverture du compte dans le SI en cas d'absence de photo ou signature | M5: OUI | N5: CC / RR / CA | O5: 2 | P5: =H5 -> 4 | Q5: =I5/O5 -> 1.5 | R5: =P5*Q5 -> 6
E6: • Défaut dans la conformité des piéces d'identité (Présence de clients ayant plusieurs pièces différentes) | F6: Risque de non-conformité Risque de fraude | G6: Risque de Fraude | H6: 5 | I6: 1 | J6: =H6*I6 -> 5 | L6: Vérifier l'authenticité des pièces d'identité et s'assurer qu'elles ne sont pas expirées | N6: CC / RR / CA | O6: 2 | P6: =H6 -> 5 | Q6: =I6/O6 -> 0.5 | R6: =P6*Q6 -> 2.5
E7: • Absence de prélévement des frais de tenue de compte pour défaut de provision (Manque de suivi sur la gestion de la clientèle), Perte de revenus | F7: Risque de pertes financières Risque opérationnel | G7: Risque opérationnel | H7: 4 | I7: 1 | J7: =H7*I7 -> 4 | L7: Prélèvement automatique des FTC paramétré dans le système | M7: oui | N7: CC / RR / CA IT | O7: 2 | P7: =H7 -> 4 | Q7: =I7/O7 -> 0.5 | R7: =P7*Q7 -> 2
E8: Vérification originaux des statuts et pv nomination du gérant ou du Directeur Général pour les SA ; SARL ; SUARL | F8: Risque de non-conformité Risque de fraude | G8: Risque de Fraude | H8: 3 | I8: 3 | J8: =H8*I8 -> 9 | L8: Type de document à receuillir déjà préétabli a l'aide d'une checklist | M8: oui | N8: CC / RR / CA | O8: 2 | P8: =H8 -> 3 | Q8: =I8/O8 -> 1.5 | R8: =P8*Q8 -> 4.5
E9: Incomplétude des dossiers d'ouverture de compte | F9: Risque opérationnel Risque de non-conformité | G9: Risque opérationnel | H9: 4 | I9: 1 | J9: 8 | L9: Mise en place d'une cheklist recensant les documents à fournir | M9: OUI | N9: CC/CA | O9: 3 | P9: 4 | Q9: =I9/O9 -> 0.33333333 | R9: =P9*Q9 -> 1.3333333
E10: Absence de liste des clients décédés | F10: Risque opérationnel Risque de non-conformité | G10: Risque opérationnel | H10: 4 | I10: 4 | J10: 16 | L10: Mettre en place une liste exhaustive des clients décédés | M10: NON | N10: AGENCE/OPS RISQUE | O10: 1 | P10: 4 | Q10: =I10/O10 -> 4 | R10: =P10*Q10 -> 16
E11: Mauvaise gestion des comptes des clients décédés | F11: Risque de fraude | G11: Risque de Fraude | H11: 4 | I11: 3 | J11: 12 | L11: Procedure de gestion des comptes des cleints décédés retracant les dispositions à mettre en œuvre | M11: OUI | N11: AGENCE/OPS/CONTRÔLE/ RISQUE | O11: 2 | P11: 4 | Q11: =I11/O11 -> 1.5 | R11: =P11*Q11 -> 6
E12: Fraude sur l'enrolement des produits digitaux et les cartes prépayées (Exemple : Création de profil, Modification des informations personnelles…) | F12: Risque opérationnel Risque de fraude | G12: Risque de Fraude | H12: 4 | I12: 3 | J12: =H12*I12 -> 12 | L12: Procedure a double validation mis en place avec initiateur et validateur | M12: Oui | N12: CC / RR / CA/ MONETIQUE | O12: 2 | P12: =H12 -> 4 | Q12: =I12/O12 -> 1.5 | R12: =P12*Q12 -> 6
E13: • Modification de type de compte dans le SI (Compte courant en compte épargne) | F13: Risque de conformité Risque de fraude | G13: Risque de Fraude | H13: 4 | I13: 1 | J13: =H13*I13 -> 4 | L13: Rendre impossible dans le SI, la modification du type de compte. | M13: OUI | N13: CC / RR / CA | O13: 2 | P13: =H13 -> 4 | Q13: =I13/O13 -> 0.5 | R13: =P13*Q13 -> 2
E14: Défaut dans la modification des packs (fiche non signée, frais non prélevés, code catégorie non modifié…) | F14: Risque opérationnel Perte financière | G14: Risque opérationnel | H14: 4 | I14: 2 | J14: =H14*I14 -> 8 | L14: Respecter vigoureusement la procédure de modification de pack | M14: NON | N14: CC / RR / CA | O14: 2 | P14: =H14 -> 4 | Q14: =I14/O14 -> 1 | R14: =P14*Q14 -> 4
E15: Défaut dans l'établissement des procurations liées aux comptes mandataires | F15: Risque opérationnel Risque de fraude | G15: Risque de Fraude | H15: 4 | I15: 3 | J15: =H15*I15 -> 12 | L15: Blocage de la création des mandataires en l'absence de procuration reçues | M15: OUI | N15: CC / RR / CA | O15: 2 | P15: =H15 -> 4 | Q15: =I15/O15 -> 1.5 | R15: =P15*Q15 -> 6
E16: • Ouverture ou fermeture incomplète des comptes dans Flexcub (comptes en instance d'ouverture, comptes à valider, demande clôture, à clôturer) | F16: Risque de conformité | G16: Risque opérationnel | H16: 4 | I16: 2 | J16: =H16*I16 -> 8 | L16: Existence de procedure d'ouverture ou de fermeture de compte | M16: OUI | N16: CC / RR / CA | O16: 2 | P16: =H16 -> 4 | Q16: =I16/O16 -> 1 | R16: =P16*Q16 -> 4
E17: • Mauvais archivage des dossiers d'ouverture de compte | F17: Risque de pertes de document | G17: Risque opérationnel | H17: 4 | I17: 1 | J17: =H17*I17 -> 4 | L17: Création du service archve | M17: OUI | N17: CC / RR / CA/Archive | O17: 2 | P17: =H17 -> 4 | Q17: =I17/O17 -> 0.5 | R17: =P17*Q17 -> 2
E18: • Manque de suivi des fermetures de compte Client | F18: Risque opérationnel Risque de conformité | G18: Risque opérationnel | H18: 4 | I18: 4 | J18: =H18*I18 -> 16 | L18: Mise en place d'une procédure de fermeture de compte | M18: NON | N18: CC / RR / CA/IT | O18: 2 | P18: =H18 -> 4 | Q18: =I18/O18 -> 2 | R18: =P18*Q18 -> 8
E19: Non-respect des horaires d'ouverture des agences | F19: Risque d'image | G19: Risque stratégique | H19: 4 | I19: 1 | J19: =H19*I19 -> 4 | L19: Procedure d'ouverture et de fermeture des agences | M19: OUI | N19: CC / RR / CA | O19: 2 | P19: =H19 -> 4 | Q19: =I19/O19 -> 0.5 | R19: =P19*Q19 -> 2
E20: Insuffisance dans les mesures de modification de signature et de numéro de téléphone | F20: Risque de fraude | G20: Risque de Fraude | H20: 4 | I20: 2 | J20: =H20*I20 -> 8 | L20: Création d'une fiche de modification des informations du client | M20: OUI | N20: CC / RR / CA | O20: 2 | P20: =H20 -> 4 | Q20: =I20/O20 -> 1 | R20: =P20*Q20 -> 4
E21: • Non prise en charge des demandes de prêt en agence | F21: Mauvaise qualité de service Risque lié à la mission commerciale | G21: Risque stratégique | H21: 4 | I21: 1 | J21: =H21*I21 -> 4 | L21: Assurer un suivi ou monitoring via Tracking crédit de toutes les demandes de prêt | M21: OUI | N21: CC / RR / CA | O21: 1 | P21: =H21 -> 4 | Q21: =I21/O21 -> 1 | R21: =P21*Q21 -> 4
E22: • Non prélèvement des frais de demande de prêt | F22: Risque de pertes financières Risque opérationnel | G22: Risque opérationnel | H22: 4 | I22: 2 | J22: =H22*I22 -> 8 | L22: Veiller à respecter rigoureusement la procédure mise en place | M22: OUI | N22: CC / RR / CA | O22: 2 | P22: =H22 -> 4 | Q22: =I22/O22 -> 1 | R22: =P22*Q22 -> 4
E23: Non réalisation/matérialisation du call back au client lors de la validation d'un ordre de virement | F23: Risque de fraude | G23: Risque de Fraude | H23: 5 | I23: 2 | J23: =H23*I23 -> 10 | L23: Veiller respecter rigoureusement la procédure de traitement des ordres de virement | M23: OUI | N23: CC / RR / CA/ CREDIT | O23: 2 | P23: =H23 -> 5 | Q23: =I23/O23 -> 1 | R23: =P23*Q23 -> 5
... E27: • Défaut sur la qualité de service délivrée en Agence | F27: Risque lié à la mission commerciale | G27: Risque stratégique | H27: 4 | I27: 1 | J27: =H27*I27 -> 4 | L27: S'assurer d'une bonne qualité des ressources humaines / favoriser des formations et sensibilisations régulières | M27: OUI | N27: CC / RR / CA | O27: 2 | P27: =H27 -> 4 | Q27: =I27/O27 -> 0.5 | R27: =P27*Q27 -> 2
D28: Gestion des caisses | E28: • Non réalisation du pointage systématique des tickets de caisses et de l'inventaire des espèces quotidiennement par un staff autre que le caissier lui-même. | F28: Risque opérationnel | G28: Risque opérationnel | H28: 3 | I28: 2 | J28: =H28*I28 -> 6 | L28: Mise en place du contrôle de niveau 1 | M28: OUI | N28: Chef D'agence / Chef Caisse | O28: 1 | P28: =H28 -> 3 | Q28: =I28/O28 -> 2 | R28: =P28*Q28 -> 6
E29: • Dépassement de la limite d'encaisse journalière autorisée – ‘’daily overnight limit’’ | F29: Risque opérationnel Risque de pertes financières en cas de sinistre | G29: Risque opérationnel | H29: 4 | I29: 2 | J29: =H29*I29 -> 8 | L29: Diffusion d'une note de service fixant les plafond d'encaisse | M29: OUI | N29: Chef D'agence / Chef Caisse | O29: 2 | P29: =H29 -> 4 | Q29: =I29/O29 -> 1 | R29: =P29*Q29 -> 4
E30: Mauvaise gestion des approvisionnements et délestages en banque | F30: Risque de fraude | G30: Risque de Fraude | H30: 5 | I30: 4 | J30: =H30*I30 -> 20 | L30: Respect strict du montant limite par convoi et présence obligatoire d'un garde national | M30: OUI(la frèquence de l'approvisionnement des caisses est faible) | N30: OPS/Chef D'agence / Chef Caisse | O30: 2 | P30: =H30 -> 5 | Q30: =I30/O30 -> 2 | R30: =P30*Q30 -> 10
E31: • Retrait fictif sur compte client | F31: Risque de fraude | G31: Risque de Fraude | H31: 5 | I31: 2 | J31: =H31*I31 -> 10 | L31: Systéme alerte sms fonctionnel pour tous les comptes clients. | M31: OUI (mais l'alerte SMS n'est pas fonctionnel pour le moment) | N31: Chef D'agence / Chef Caisse | O31: 2 | P31: =H31 -> 5 | Q31: =I31/O31 -> 1 | R31: =P31*Q31 -> 5
E32: • Non détection des cas de faux billets | F32: Risque de fraude Risque de pertes financières | G32: Risque de Fraude | H32: 5 | I32: 3 | J32: =H32*I32 -> 15 | L32: Mise a disposition de detecteurde faux billet au niveau de chaque caisse | M32: NON | N32: Chef D'agence / Chef Caisse | O32: 2 | P32: =H32 -> 5 | Q32: =I32/O32 -> 1.5 | R32: =P32*Q32 -> 7.5
E33: Absence de validation des annulations d'opèrations de caisse | F33: Risque de fraude/Vol | G33: Risque de Fraude | H33: 4 | I33: 3 | J33: =H33*I33 -> 12 | L33: Validation système paramétré au niveaudu chef d'agence pour chaque opération | M33: NON | N33: Contrôle Interne/Chef agence | O33: 3 | P33: =H33 -> 4 | Q33: =I33/O33 -> 1 | R33: =P33*Q33 -> 4
E34: • Différence de caisse | F34: Risque de pertes financières Risque opérationnel | G34: Risque de Fraude | H34: 5 | I34: 2 | J34: =H34*I34 -> 10 | L34: suivi quotidien des caisses et des contrôles inopinés de caisse | M34: OUI | N34: Chef D'agence / Superviseur/ Contrôle | O34: 3 | P34: =H34 -> 5 | Q34: =I34/O34 -> 0.66666667 | R34: =P34*Q34 -> 3.3333333
D35: Gestion de la sécurité et Assurance | E35: • Absence d'alarme anti-intruision | F35: Risque de vol | G35: Risque opérationnel | H35: 3 | I35: 1 | J35: =H35*I35 -> 3 | L35: Mettre en place des alarmes anti-intruision | M35: OUI | N35: IT | O35: 2 | P35: =H35 -> 3 | Q35: =I35/O35 -> 0.5 | R35: =P35*Q35 -> 1.5
E36: • Absence détecteur de fumée et extincteur | F36: Risque de perte de données | G36: Risque opérationnel | H36: 3 | I36: 1 | J36: =H36*I36 -> 3 | L36: Mettre en place des détecteurs de fumée et extincteur | M36: OUI (Dysfonctionnement du dispositif de détecteur de fumée en place (Inventaire en cours pour régulariser le dysfonctionnement) | N36: IT/Achat Logistique | O36: 1 | P36: =H36 -> 3 | Q36: =I36/O36 -> 1 | R36: =P36*Q36 -> 3
E37: • Gestion des clés du coffre-fort ou accès coffre effectuée par une seule personne | F37: Risque opérationnel Risque de vol, fraude | G37: Risque de Fraude | H37: 5 | I37: 2 | J37: =H37*I37 -> 10 | L37: Procédure de gestion des clés du coffre et l'accès au coffre. | M37: OUI | N37: Contrôle interne/CA | O37: 2 | P37: =H37 -> 5 | Q37: =I37/O37 -> 1 | R37: =P37*Q37 -> 5
E38: Absence de politique de sécurité physique et locaux sensibles. | F38: Risque de pertes financières en cas de sinistre | G38: Risque opérationnel | H38: 4 | I38: 2 | J38: =H38*I38 -> 8 | L38: Veiller à ce que les exigences liées au dispositif de sécurité sont en place. | M38: NON | N38: Contrôle interne | O38: 2 | P38: =H38 -> 4 | Q38: =I38/O38 -> 1 | R38: =P38*Q38 -> 4
E39: • Absence d'agent de sécurité armé en agence | F39: Risque opérationnel | G39: Risque opérationnel | H39: 5 | I39: 2 | J39: =H39*I39 -> 10 | L39: Veiller à ce que les agents armés soient présent en agence pour veiller à la sécurité des biens et des personnes | M39: OUI(il faudra vérifier si c'est disponible dans tous les agences) | N39: Contrôle interne | O39: 2 | P39: =H39 -> 5 | Q39: =I39/O39 -> 1 | R39: =P39*Q39 -> 5
A40: AGENCES | E40: EVALUATION INTRINSEQUE | H40: =+ROUND(IFERROR(AVERAGE(H5:H39),0),0) -> 4 | I40: =+ROUND(IFERROR(AVERAGE(I5:I39),0),0) -> 2 | J40: =H40*I40 -> 8 | L40: EVALUATION RESIDUELLE | O40: =+ROUND(IFERROR(AVERAGE(O5:O39),0),0) -> 2 | P40: =+ROUND(IFERROR(AVERAGE(P5:P39),0),0) -> 4 | Q40: =+ROUND(IFERROR(AVERAGE(Q5:Q39),0),0) -> 1 | R40: =+ROUND(IFERROR(AVERAGE(R5:R39),0),0) -> 5
F43: Risque de Fraude | G43: =COUNTIF(G5:G40,F43) -> 17
F44: Risque opérationnel | G44: =COUNTIF(G5:G40,F44) -> 15
F45: Risque stratégique | G45: =COUNTIF(G5:G40,F45) -> 3
F46: Risque de crédit | G46: =COUNTIF(G5:G40,F46) -> 0
...

Sheet Feuil2
A1: Risque de Fraude
A2: Risque opérationnel
A3: Risque stratégique
A4: Risque de crédit
A5: Risque de liquidité
A6: Risque réglementaire
A7: Risque exogéne

Sheet RESSOURCES HUMAINES
A1: ANALYSE DES RISQUES OPERATIONNELS - RESSOURCES HUMAINES
A2: N° | B2: PROCESSUS | C2: RATIO | D2: SOUS PROCESSUS | E2: EXCEPTIONS MAJEURES CONSTATEES | F2: RISQUES CORRELES | G2: FAMILLE DE RISQUE | H2: Gravité | I2: Probabilité | J2: Risque brut (Rb) | K2: Justification de l'évaluation en cas de risque jugé critique | L2: DISPOSITIF DE PREVENTION ET DE CONTRÔLE | P2: Gravité résiduelle | Q2: Probabilité résiduelle | R2: Risque résiduel (Rr)
H4: G | I4: P | J4: est égal à GxP | L4: Description du dispositif | M4: Dispositif existant ou Non | N4: Owner du Contrôle | O4: Efficacité du dispositif | P4: G | Q4: Pr | R4: est égal à GxP
A5: 8 | B5: RESSOURCES HUMAINES | C5: 0.05 | D5: Gestion administrative du personnel & Affaires sociales | E5: '• Dossier du personnel incomplet | F5: Faiblesse dans l'identification du staff Risque de document fictif | G5: Risque opérationnel | H5: 3 | I5: 1 | J5: =H5*I5 -> 3 | L5: Contrôle systématique du dossier de personnel pour le nouveau entrant | M5: OUI | N5: CONTRÔLE INTERNE | O5: 2 | P5: =H5 -> 3 | Q5: =I5/O5 -> 0.5 | R5: =P5*Q5 -> 1.5
E6: Mauvais archivage des dossiers du personnel | F6: Risque de perte Risque de divulgation d'informations sensibles | G6: Risque opérationnel | H6: 3 | I6: 2 | J6: =H6*I6 -> 6 | L6: Classement chronologique mis en place avec stokage dans unenarmoire unifuge | M6: OUI | N6: RRH | O6: 2 | P6: =H6 -> 3 | Q6: =I6/O6 -> 1 | R6: =P6*Q6 -> 3
E7: • Non-respect du processus de recrutement | F7: Risque d'inadéquation entre le profil recherché et le besoin réel Risque de recrutement arbitraire | G7: Risque opérationnel | H7: 4 | I7: 2 | J7: =H7*I7 -> 8 | L7: Procedue de gestion du recritement existant | M7: OUI | N7: RRH | O7: 2 | P7: =H7 -> 4 | Q7: =I7/O7 -> 1 | R7: =P7*Q7 -> 4
E8: Non-conformité des dossiers du personnel | F8: Risque de fraude | G8: Risque de Fraude | H8: 4 | I8: 2 | J8: =H8*I8 -> 8 | L8: Mis en place d'une checklist des documents a fournir avant le démarrage | N8: RRH | O8: 2 | P8: =H8 -> 4 | Q8: =I8/O8 -> 1 | R8: =P8*Q8 -> 4
E9: Défaut de provisionnement des indemnités de départ à la retraite | F9: Risque de non-conformité | G9: Risque opérationnel | H9: 4 | I9: 2 | J9: =H9*I9 -> 8 | L9: S'assurer que les provisions de départ à la retraite sont constituées | N9: RRH | O9: 2 | P9: =H9 -> 4 | Q9: =I9/O9 -> 1 | R9: =P9*Q9 -> 4
E10: Non respect de la procédure des avances/accomptes sur salaires | F10: Risque opérationnel | G10: Risque opérationnel | H10: 3 | I10: 1 | J10: =H10*I10 -> 3 | L10: Mise en plae d'une politique encadrant l'activité | N10: RRH | O10: 2 | P10: =H10 -> 3 | Q10: =I10/O10 -> 0.5 | R10: =P10*Q10 -> 1.5
E11: Absence de mise à jour du registre de l'employeur | F11: Risque de non-conformité | G11: Risque opérationnel | H11: 3 | I11: 1 | J11: =H11*I11 -> 3 | L11: Mettre à jour systématiquement le registre d'employeur | M11: OUI | N11: RRH | O11: 3 | P11: 4 | Q11: =I11/O11 -> 0.33333333 | R11: =P11*Q11 -> 1.3333333
E12: Défaut de réalisation du PIC pour les nouveaux entrants | F12: Risque opérationnel | G12: Risque opérationnel | H12: 4 | I12: 3 | J12: =H12*I12 -> 12 | L12: Etablir et exécuter un planning d'immersion pour les nouveaux rentrants | M12: OUI | N12: RRH | O12: 3 | P12: 4 | Q12: =I12/O12 -> 1 | R12: =P12*Q12 -> 4
E13: Mauvaise gestion des prêts octroyés au personnel (non respect de la quotité cessible, échéance non prélevée…) | F13: Risque opérationnel | G13: Risque opérationnel | H13: 5 | I13: 3 | J13: =H13*I13 -> 15 | L13: Mise en plae d'une politique encadrant l'activité | M13: OUI | N13: RRH | O13: 2 | P13: 5 | Q13: =I13/O13 -> 1.5 | R13: =P13*Q13 -> 7.5
E14: Non-respect du dress code par le personnel | F14: Risque opérationnel, d'image | G14: Risque opérationnel | H14: 3 | I14: 3 | J14: =H14*I14 -> 9 | L14: Sensibiliser le personnel sur le respect du dress code/Faire des sessions de rappel | M14: NON | N14: RRH | O14: 1 | P14: 4 | Q14: =I14/O14 -> 3 | R14: =P14*Q14 -> 12
E15: Recrutement du personnel non budgétisé | F15: Risque de recrutement arbitraire | G15: Risque opérationnel | H15: 3 | I15: 3 | J15: =H15*I15 -> 9 | L15: Mettre en place une procédure de recrutement non budgétisé | M15: NON | N15: RRH | O15: 2 | P15: 4 | Q15: =I15/O15 -> 1.5 | R15: =P15*Q15 -> 6
D16: Gestion des départs | E16: Non restitution des outils et matériels de travail lors des départs (check-list départ non réalisé) | F16: Risque de vol | G16: Risque de Fraude | H16: 2 | I16: 2 | J16: =H16*I16 -> 4 | L16: Mise en place check-list départ systématiquement avec materiel a rendre | M16: OUI | N16: RRH | O16: 2 | P16: =+H16 -> 2 | Q16: =I16/O16 -> 1 | R16: =P16*Q16 -> 2
E17: Non désactivation des accès (messagerie, système, autres…) du staff sortant | F17: Risque opérationnel Risque de fraude | G17: Risque de Fraude | H17: 2 | I17: 2 | J17: =H17*I17 -> 4 | L17: Communication systématique sur les départ aux IT et Contrôle interne | M17: OUI | N17: RRH | O17: 2 | P17: =H17 -> 2 | Q17: =I17/O17 -> 1 | R17: =P17*Q17 -> 2
E18: Non-suppression du staff du logiciel de paie | F18: Risque opérationnel Risque de fraude | G18: Risque de Fraude | H18: 5 | I18: 2 | J18: =H18*I18 -> 10 | L18: Supprimer le staff sortant du logiciel de paie | M18: OUI | N18: RRH | O18: 2 | P18: =H18 -> 5 | Q18: =I18/O18 -> 1 | R18: =P18*Q18 -> 5
D19: Politique de rémunération et Paie | E19: • Non-conformité règlementaire des traitements salariaux (grille convention collective APSFD) | F19: Risque de non exhaustivité de la paie | G19: Risque réglementaire | H19: 4 | I19: 2 | J19: =H19*I19 -> 8 | L19: S'assurer de la conformité des traitements de salaire | M19: OUI | N19: RRH | O19: 2 | P19: =H19 -> 4 | Q19: =I19/O19 -> 1 | R19: =P19*Q19 -> 4
E20: • Non détermination des provisions pour congé et retraite et/ou non comptabilisation des provisions pour congé et retraite | F20: Risque de redressement | G20: Risque réglementaire | H20: 4 | I20: 2 | J20: =H20*I20 -> 8 | L20: S'assurer de la conformité des traitements de congés | M20: OUI | N20: RRH | O20: 2 | P20: =H20 -> 4 | Q20: =I20/O20 -> 1 | R20: =P20*Q20 -> 4
E21: • Absence de déclarations fiscales et sociales et/ou erreur dans les déclarations fiscales et sociales liées à la paie | F21: Risque de redressement | G21: Risque réglementaire | H21: 4 | I21: 2 | J21: =H21*I21 -> 8 | L21: S'assurer de la conformité des déclarations sociales effectuées. | M21: OUI | N21: RRH | O21: 2 | P21: =H21 -> 4 | Q21: =I21/O21 -> 1 | R21: =P21*Q21 -> 4
E22: Manque de confidentialité des données de la paie | F22: Conflit d'intérêts | G22: Risque stratégique | H22: 3 | I22: 3 | J22: =H22*I22 -> 9 | L22: S'assurer que l'accès au logiciel de la paie est restreint dans le système et le dossier du personnel | M22: NON | N22: RRH | O22: 2 | P22: =H22 -> 3 | Q22: =I22/O22 -> 1.5 | R22: =P22*Q22 -> 4.5
E23: • Absence d'un outil de gestion de la paie | F23: Risque d'erreur opérationnelle | G23: Risque opérationnel | H23: 3 | I23: 3 | J23: =H23*I23 -> 9 | L23: Existence d'un outils de gestion de la paie | M23: OUI | N23: RRH | O23: 2 | P23: =H23 -> 3 | Q23: =I23/O23 -> 1.5 | R23: =P23*Q23 -> 4.5
D24: Appréciation des performance - Evaluation | E24: '• Non-respect du processus d'évaluation | F24: Conflit d'intérêts | G24: Risque stratégique | H24: 1 | I24: 1 | J24: =H24*I24 -> 1 | L24: Mise n place d'une procedure d'évaluataion | M24: OUI | N24: RRH | O24: 2 | P24: =H24 -> 1 | Q24: =I24/O24 -> 0.5 | R24: =P24*Q24 -> 0.5
E25: • Non évaluation des staffs et/ou Critères d’évaluation non définis ou non adéquats | F25: Méconnaissance des critéres d'évaluation | G25: Risque opérationnel | H25: 1 | I25: 1 | J25: =H25*I25 -> 1 | L25: Suivi semestriel sur les évaluations | M25: OUI | N25: RRH | O25: 2 | P25: =H25 -> 1 | Q25: =I25/O25 -> 0.5 | R25: =P25*Q25 -> 0.5
E26: • Evaluation non objective | F26: Conflit d'intérêts | G26: Risque stratégique | H26: 4 | I26: 2 | J26: =H26*I26 -> 8 | L26: Procedure des gestion des évaluation mis en place prenant en compte ce point | M26: OUI | N26: RRH | O26: 2 | P26: =H26 -> 4 | Q26: =I26/O26 -> 1 | R26: =P26*Q26 -> 4
D27: Gestion des congés | E27: Exixtance de solde de congés supérieurs à la norme | F27: Perturbation/baisse de rendement | G27: Risque opérationnel | H27: 5 | I27: 3 | J27: =H27*I27 -> 15 | P27: =H27 -> 5
E28: Non élaboration d'un fichier annuel de suivi des congés | F28: Risque opérationnel | G28: Risque opérationnel | H28: 2 | I28: 2 | J28: =H28*I28 -> 4 | L28: Outils de gestion des congés existant | M28: OUI | N28: RRH | O28: 2 | P28: =H28 -> 2 | Q28: =I28/O28 -> 1 | R28: =P28*Q28 -> 2
D29: Formation | E29: Non évaluation annuelle et suivi des besoins de formation du personnel | F29: Non renforcement des compétences Démotivation du personnel | G29: Risque stratégique | H29: 4 | I29: 4 | J29: =H29*I29 -> 16 | L29: Mettre en place un tableau de suivi des formations et les exécuter au cours de l'année | M29: OUI | N29: RRH | O29: 2 | P29: =H29 -> 4 | Q29: =I29/O29 -> 2 | R29: =P29*Q29 -> 8
D30: Gestions des carrières | E30: Absence d'une politique de conservation ou rétention du personnel | F30: Risque d'image , Risque réputationnel | G30: Risque stratégique | H30: 4 | I30: 4 | J30: =H30*I30 -> 16 | L30: Respect de la politique de la Gestion prévisionnelle des emplois et des carrières ( GPEC ) | M30: NON | N30: RRH | O30: 2 | P30: =H30 -> 4 | Q30: =I30/O30 -> 2 | R30: =P30*Q30 -> 8
E31: Absence d'une politique de développement du personnel (formation, suivi managérial) | F31: Risque d'image , Risque réputationnel | G31: Risque stratégique | H31: 3 | I31: 2 | J31: =H31*I31 -> 6 | L31: S'assurer de la MEP d'une politique de capacitation du personnel | M31: NON | N31: RRH | O31: 2 | P31: =H31 -> 3 | Q31: =I31/O31 -> 1 | R31: =P31*Q31 -> 3
D32: Bien être au travail/Qualité de vie au travail | E32: Harcellement (violence physique ou verbale) | F32: Risque de départ; Risque de dégradation de la santé mentale Risque d'image de l'Intitution | G32: Risque stratégique | H32: 4 | I32: 2 | J32: =H32*I32 -> 8 | L32: Politique de sanction mis en place | M32: oui | N32: RRH | O32: 3 | P32: =H32 -> 4 | Q32: =I32/O32 -> 0.66666667 | R32: =P32*Q32 -> 2.6666667
