Workbook

Sheet Accueil
D1: Entité: | E1: COFINA Togo | I1: Page d'accueil | N1: =AVERAGE(B8:B27,D3,I3,COUNTA(Contracts!B3:R4)/34,COUNTA('✅ Projets 2026'!#REF!)/60) -> 0.94999342
D3: =QG!B2 -> 1 | I3: =Secu!B2 -> 1
B6: Services IT
B7: Taux de remplissage | C7: Application | D7: Existant | E7: Nom de la solution | F7: Editeur | G7: Importance | H7: Version | I7: Dernière version | J7: SLA existant | K7: SaaS ou sur site | L7: # users | M7: # licences | N7: Type de licences | O7: Niveau de personnalisation | P7: Sauvegardes | Q7: ETP Support | R7: ETP Changes | S7: Archi HD
B8: =SUM(CBS!$E$7:$E$63)/COUNT(CBS!$E$7:$E$63) -> 1 | D8: oui | E8: =CBS!$C$9 -> Oracle FLEXCUBE Universal Banking | F8: =CBS!$C$8 -> Oracle | G8: =CBS!$C$14 -> Primoridal | H8: =CBS!$C$10 -> Version 14.7 | I8: =CBS!$C$11 -> Version 14.8 | J8: =LEFT(CBS!$C$38,3) -> Oui | K8: =CBS!$C$45 -> On-site | L8: =CBS!$C$28 -> 1000 pour tout le groupe | M8: =CBS!$C$32 -> VOIR IT GROUPE | N8: =CBS!$C$33 -> Nominatives | O8: =CBS!$C$23 -> Moyen | P8: =CBS!$C$59 -> Oui | Q8: =CBS!$C$39 -> 1. Niveau 1 : o Nombre d'ETP : 4 o Répartition des Activités : Résolution des tickets de premier niveau, support de base aux utilisateurs, gestion des demandes simples et Analyse des incidents 2. Niveau 2 : o Nombre d'ETP : 5 o Entité : Holding o Répartition des Activités : Analyse des incidents plus complexes, gestion des escalades du niveau 1, résolution de problèmes techniques avancés. o Compétences : Expertise technique, capacité à résoudre des problèmes complexes. o Rôles : Technicien Support Niveau 2 3. Niveau 3 : o Nombre d'ETP : DEFINIR o Entité : PROVIDER o Répartition des Activités : Gestion des problèmes critiques, développement de solutions, coordination avec les équipes de développement. o Compétences : Expertise approfondie, compétences en développement et en gestion des incidents majeurs. o Rôles : Ingénieur Support Niveau 3 | R8: =CBS!$C$40 -> Holding : ETP dédiés : 5 Filiale : ETP dédiés : 1 | S8: =CBS!$C$52 -> Non
E9: NAFA
B10: =SUM(LOS!$E$7:$E$61)/COUNT(LOS!$E$7:$E$61) -> 1 | D10: oui | E10: =LOS!$C$9 -> CREDITFLOW | F10: =IF(LOS!$C$7="Développement interne","COFINA",LOS!$C$8) -> EDAN | G10: =LOS!$C$14 -> Moyen | H10: =LOS!$C$10 -> 1.0 | I10: =LOS!$C$11 -> 1.0 | J10: =LEFT(LOS!$C$36,3) -> Non | K10: =LOS!$C$43 -> Cloud | L10: =LOS!$C$26 -> environ 50 | M10: =LOS!$C$30 -> VOIR IT GROUPE | N10: =LOS!$C$31 -> VOIR IT GROUPE | O10: =LOS!$C$21 -> Moyen | P10: =LOS!$C$57 -> Non | Q10: =LOS!$C$37 -> 1. Niveau 1 : o Nombre d'ETP : 3 o Répartition des Activités : Résolution des tickets de premier niveau, support de base aux utilisateurs, gestion des demandes simples et Analyse des incidents 2. Niveau 2 : o Nombre d'ETP : A DEFINIR o Entité : Holding o Répartition des Activités : Analyse des incidents plus complexes, gestion des escalades du niveau 1, résolution de problèmes techniques avancés. o Compétences : Expertise technique, capacité à résoudre des problèmes complexes. o Rôles : Technicien Support Niveau 2 3. Niveau 3 : o Nombre d'ETP : DEFINIR par IT GROUPE o Entité : PROVIDER o Répartition des Activités : Gestion des problèmes critiques, développement de solutions, coordination avec les équipes de développement. o Compétences : Expertise approfondie, compétences en développement et en gestion des incidents majeurs. o Rôles : Ingénieur Support Niveau 3 | R10: =LOS!$C$38 -> Holding : ETP dédiés : 0 Filiale : ETP dédiés : 0 | S10: =LOS!$C$50 -> Non
B11: =SUM(AB!$E$7:$E$61)/COUNT(AB!$E$7:$E$61) -> 1 | D11: OUI | E11: =AB!$C$9 -> KIWI | F11: =IF(AB!$C$7="Développement interne","COFINA",AB!$C$8) -> SMARTS SOLUTIONS | G11: =AB!$C$14 -> Moyen | H11: =AB!$C$10 -> 1.7 | I11: =AB!$C$11 -> 1.7.5 | J11: =LEFT(AB!$C$36,3) -> Non | K11: =AB!$C$43 -> Cloud | L11: =AB!$C$26 -> VOIR IT GROUPE | M11: =AB!$C$30 -> VOIR IT GROUPE | N11: =AB!$C$31 -> Nominatives | O11: =AB!$C$21 -> Haut | P11: =AB!$C$57 -> Oui | Q11: =AB!$C$37 -> 1. Niveau 1 : o Nombre d'ETP : 3 o Répartition des Activités : Résolution des tickets de premier niveau, support de base aux utilisateurs, gestion des demandes simples et Analyse des incidents 2. Niveau 2 : o Nombre d'ETP : 5 o Entité : Holding o Répartition des Activités : Analyse des incidents plus complexes, gestion des escalades du niveau 1, résolution de problèmes techniques avancés. o Compétences : Expertise technique, capacité à résoudre des problèmes complexes. o Rôles : Technicien Support Niveau 2 3. Niveau 3 : o Nombre d'ETP : DEFINIR o Entité : PROVIDER o Répartition des Activités : Gestion des problèmes critiques, développement de solutions, coordination avec les équipes de développement. o Compétences : Expertise approfondie, compétences en développement et en gestion des incidents majeurs. o Rôles : Ingénieur Support Niveau 3 | R11: =AB!$C$38 -> Holding : ETP dédiés : 5 Filiale : ETP dédiés : 1 | S11: =AB!$C$50 -> Non
B12: =SUM(MB!$E$7:$E$60)/COUNT(MB!$E$7:$E$60) -> 1 | D12: oui | E12: =IF(MB!$C$7="Non prévu",MB!$C$7,MB!$C$9) -> COFINA MOBILE + | F12: =IF(MB!$C$7="Développement interne","COFINA",MB!$C$8) -> SMARTS SOLUTIONS | G12: =MB!$C$14 -> Primoridal | H12: =MB!$C$10 -> 1.7 | I12: =MB!$C$11 -> 1.7.5 | J12: =LEFT(MB!$C$35,3) -> Non | K12: =MB!$C$42 -> Cloud | L12: =MB!$C$25 -> 8600 | M12: =MB!$C$29 -> VOIR IT GROUPE | N12: =MB!$C$30 -> Nominatives | O12: =MB!$C$21 -> Très haut | P12: =MB!$C$56 -> Oui | Q12: =MB!$C$36 -> 1. Niveau 1 : o Nombre d'ETP : 4 o Répartition des Activités : Résolution des tickets de premier niveau, support de base aux utilisateurs, gestion des demandes simples et Analyse des incidents 2. Niveau 2 : o Nombre d'ETP : 5 o Entité : Holding o Répartition des Activités : Analyse des incidents plus complexes, gestion des escalades du niveau 1, résolution de problèmes techniques avancés. o Compétences : Expertise technique, capacité à résoudre des problèmes complexes. o Rôles : Technicien Support Niveau 2 3. Niveau 3 : o Nombre d'ETP : DEFINIR o Entité : PROVIDER o Répartition des Activités : Gestion des problèmes critiques, développement de solutions, coordination avec les équipes de développement. o Compétences : Expertise approfondie, compétences en développement et en gestion des incidents majeurs. o Rôles : Ingénieur Support Niveau 3 | R12: =MB!$C$37 -> Holding : ETP dédiés : 5 Filiale : ETP dédiés : 1 | S12: =MB!$C$49 -> Oui
B13: =SUM(IB!$E$7:$E$61)/COUNT(IB!$E$7:$E$61) -> 1 | D13: non | E13: =IF(IB!$C$7="Non prévu",IB!$C$7,IB!$C$9) -> Non prévu | F13: =IF(IB!$C$7="Développement interne","COFINA",IB!$C$8) -> 0 | G13: =IB!$C$14 -> Moyen | H13: =IB!$C$10 -> 0 | I13: =IB!$C$11 -> 0 | J13: =LEFT(IB!$C$36,3) | K13: =IB!$C$43 -> 0 | L13: =IB!$C$26 -> 0 | M13: =IB!$C$30 -> 0 | N13: =IB!$C$31 -> 0 | O13: =IB!$C$21 -> 0 | P13: =IB!$C$57 -> 0 | Q13: =IB!$C$37 -> 0 | R13: =IB!$C$38 -> 0 | S13: =IB!$C$50 -> 0
B14: =SUM(AML!$E$7:$E$62)/COUNT(AML!$E$7:$E$62) -> 0.98113208 | D14: OUI | E14: =IF(AML!$C$7="Non prévu",AML!$C$7,AML!$C$9) -> REIS | F14: =IF(AML!$C$7="Développement interne","COFINA",AML!$C$8) -> Vneuron | G14: =AML!$C$14 -> Critique | H14: =AML!$C$10 -> Vneuron © Reis™ RCS 4.1 | I14: =AML!$C$11 -> 4.1 | J14: =LEFT(AML!$C$36,3) -> Oui | K14: =AML!$C$43 -> Cloud | L14: =AML!$C$26 -> une vingtaine | M14: =AML!$C$30 -> une licence par filiale | N14: =AML!$C$31 -> Partagées | O14: =AML!$C$21 -> Très haut | P14: =AML!$C$57 -> Oui | Q14: =AML!$C$37 -> 1. Niveau 1 : o Nombre d'ETP : 4 o Répartition des Activités : Résolution des tickets de premier niveau, support de base aux utilisateurs, gestion des demandes simples et Analyse des incidents 2. Niveau 2 : o Nombre d'ETP : 5 o Entité : Holding o Répartition des Activités : Analyse des incidents plus complexes, gestion des escalades du niveau 1, résolution de problèmes techniques avancés. o Compétences : Expertise technique, capacité à résoudre des problèmes complexes. o Rôles : Technicien Support Niveau 2 3. Niveau 3 : o Nombre d'ETP : DEFINIR o Entité : PROVIDER o Répartition des Activités : Gestion des problèmes critiques, développement de solutions, coordination avec les équipes de développement. o Compétences : Expertise approfondie, compétences en développement et en gestion des incidents majeurs. o Rôles : Ingénieur Support Niveau 3 | R14: =AML!$C$38 -> Holding : ETP dédiés : 5 Filiale : ETP dédiés : 1 | S14: =AML!$C$50 -> Non
B15: =SUM(Collect!$E$7:$E$61)/COUNT(Collect!$E$7:$E$61) -> 1 | D15: non | E15: =IF(Collect!$C$7="Non prévu",Collect!$C$7,Collect!$C$9) -> Module : Collection | F15: =IF(Collect!$C$7="Développement interne","COFINA",Collect!$C$8) -> 0 | G15: =Collect!$C$14 -> Critique | H15: =Collect!$C$10 -> Version 14.7 | I15: =Collect!$C$11 -> Version 14.9 | J15: =LEFT(Collect!$C$36,3) -> VOI | K15: =Collect!$C$43 -> On-site | L15: =Collect!$C$26 -> 1000 pour tout le groupe | M15: =Collect!$C$30 -> VOIR IT GROUPE | N15: =Collect!$C$31 -> VOIR IT GROUPE | O15: =Collect!$C$21 -> Très haut | P15: =Collect!$C$57 -> Non | Q15: =Collect!$C$37 -> Niveau 1: Holding : ETP dédiés : 5 Niveau 2 : Filiale : ETP dédiés : 3 Niveau 3 : Nombre d'ETP : DEFINIR par IT GROUPE | R15: =Collect!$C$38 -> Holding : ETP dédiés : 5 Filiale : ETP dédiés : 1 | S15: =Collect!$C$50 -> Non
B16: =SUM(CRM!$E$7:$E$61)/COUNT(CRM!$E$7:$E$61) -> 1 | D16: non | E16: =IF(CRM!$C$7="Non prévu",CRM!$C$7,CRM!$C$9) -> Non prévu | F16: =IF(CRM!$C$7="Développement interne","COFINA",CRM!$C$8) -> 0 | G16: =CRM!$C$14 -> Moyen | H16: =CRM!$C$10 -> 0 | I16: =CRM!$C$11 -> 0 | J16: =LEFT(CRM!$C$36,3) | K16: =CRM!$C$43 -> 0 | L16: =CRM!$C$26 -> 0 | M16: =CRM!$C$30 -> 0 | N16: =CRM!$C$31 -> 0 | O16: =CRM!$C$21 -> 0 | P16: =CRM!$C$57 -> 0 | Q16: =CRM!$C$37 -> 0 | R16: =CRM!$C$38 -> 0 | S16: =CRM!$C$50 -> 0
B17: =IF(COUNT(CC!$E$7:$E$61)=0,1,SUM(CC!$E$7:$E$61)/COUNT(CC!$E$7:$E$61)) -> 1 | D17: non | E17: =IF(CC!$C$7="Non prévu",CC!$C$7,CC!$C$9) -> Non prévu | F17: =IF(CC!$C$7="Développement interne","COFINA",CC!$C$8) -> 0 | G17: =CC!$C$14 -> Moyen | H17: =CC!$C$10 -> 0 | I17: =CC!$C$11 -> 0 | J17: =LEFT(CC!$C$36,3) | K17: =CC!$C$43 -> 0 | L17: =CC!$C$26 -> 0 | M17: =CC!$C$30 -> 0 | N17: =CC!$C$31 -> 0 | O17: =CC!$C$21 -> 0 | P17: =CC!$C$57 -> 0 | Q17: =CC!$C$37 -> 0 | R17: =CC!$C$38 -> 0 | S17: =CC!$C$50 -> 0
B18: =SUM(DocM!$E$7:$E$61)/COUNT(DocM!$E$7:$E$61) -> 1 | D18: non | E18: =IF(DocM!$C$7="Non prévu",DocM!$C$7,DocM!$C$9) -> Non prévu | F18: =IF(DocM!$C$7="Développement interne","COFINA",DocM!$C$8) -> 0 | G18: =DocM!$C$14 -> Faible | H18: =DocM!$C$10 -> 0 | I18: =DocM!$C$11 -> 0 | J18: =LEFT(DocM!$C$36,3) | K18: =DocM!$C$43 -> 0 | L18: =DocM!$C$26 -> 0 | M18: =DocM!$C$30 -> 0 | N18: =DocM!$C$31 -> 0 | O18: =DocM!$C$21 -> 0 | P18: =DocM!$C$57 -> 0 | Q18: =DocM!$C$37 -> 0 | R18: =DocM!$C$38 -> 0 | S18: =DocM!$C$50 -> 0
B19: =SUM(BI!$E$7:$E$59)/COUNT(BI!$E$7:$E$59) -> 1 | D19: non | E19: =IF(BI!$C$7="Non prévu",BI!$C$7,BI!$C$9) -> Non prévu | F19: =IF(BI!$C$7="Développement interne","COFINA",BI!$C$8) -> 0 | G19: =BI!$C$14 -> Moyen | H19: =BI!$C$51 -> 0 | I19: =BI!$C$11 -> 0 | J19: =LEFT(BI!$C$34,3) | K19: =BI!$C$41 -> 0 | L19: =BI!$C$24 -> 0 | M19: =BI!$C$28 -> 0 | N19: =BI!$C$29 -> 0 | O19: =BI!$C$19 -> 0 | P19: =BI!$C$55 -> 0 | Q19: =BI!$C$35 -> 0 | R19: =BI!$C$36 -> 0 | S19: =BI!$C$47 -> 0
B20: =SUM(SOA!$E$7:$E$52)/COUNT(SOA!$E$7:$E$52) -> 1 | D20: non | E20: =IF(BI!$C$7="Non prévu",BI!$C$7,BI!$C$9) -> Non prévu | F20: =IF(BI!$C$7="Développement interne","COFINA",BI!$C$8) -> 0 | G20: =BI!$C$14 -> Moyen | H20: =BI!$C$51 -> 0 | I20: =BI!$C$11 -> 0 | J20: =LEFT(BI!$C$34,3) | K20: =BI!$C$41 -> 0 | L20: =BI!$C$24 -> 0 | M20: =BI!$C$28 -> 0 | N20: =BI!$C$29 -> 0 | O20: =BI!$C$19 -> 0 | P20: =BI!$C$55 -> 0 | Q20: =BI!$C$35 -> 0 | R20: =BI!$C$36 -> 0 | S20: =BI!$C$47 -> 0
B21: =SUM('ERP1'!$E$7:$E$61)/COUNT('ERP1'!$E$7:$E$61) -> 1 | D21: oui | E21: =IF('ERP1'!$C$7="Non prévu",'ERP1'!$C$7,'ERP1'!$C$9) -> Non | F21: =IF('ERP1'!$C$7="Développement interne","COFINA",'ERP1'!$C$8) -> Oui | G21: ='ERP1'!$C$14 -> 2024 | H21: ='ERP1'!$C$16 -> Très haut | I21: ='ERP1'!$C$11 -> Non | J21: =LEFT('ERP1'!$C$36,3) | K21: ='ERP1'!$C$43 -> 0 | L21: ='ERP1'!$C$26 -> Non | M21: ='ERP1'!$C$30 -> journaliere | N21: ='ERP1'!$C$31 -> Oui | O21: ='ERP1'!$C$21 -> Non | P21: ='ERP1'!$C$57 -> 0 | Q21: ='ERP1'!$C$37 -> 0 | R21: ='ERP1'!$C$38 -> 0 | S21: ='ERP1'!$C$50 -> 0
B22: =SUM('ERP2'!$E$7:$E$59)/COUNT('ERP2'!$E$7:$E$59) -> 1 | D22: oui | E22: =IF('ERP2'!$C$7="Non prévu",'ERP2'!$C$7,'ERP2'!$C$9) -> digitalisée d'évaluation des performances de COFINA | F22: =IF('ERP2'!$C$7="Développement interne","COFINA",'ERP2'!$C$8) -> COFINA | G22: ='ERP2'!$C$14 -> Moyen | H22: ='ERP2'!$C$10 -> Voir IT GROUPE | I22: ='ERP2'!$C$11 -> Voir IT GROUPE | J22: =LEFT('ERP2'!$C$34,3) -> NON | K22: ='ERP2'!$C$41 -> On-site | L22: ='ERP2'!$C$24 -> Voir IT GROUPE | M22: ='ERP2'!$C$28 -> Voir IT GROUPE | N22: ='ERP2'!$C$29 -> Voir IT GROUPE | O22: ='ERP2'!$C$19 -> Haut | P22: ='ERP2'!$C$55 -> Non | Q22: ='ERP2'!$C$35 -> 1. Niveau 1 : o Nombre d'ETP : 4 o Répartition des Activités : Résolution des tickets de premier niveau, support de base aux utilisateurs, gestion des demandes simples et Analyse des incidents 2. Niveau 2 : o Nombre d'ETP : 5 o Entité : Holding o Répartition des Activités : Analyse des incidents plus complexes, gestion des escalades du niveau 1, résolution de problèmes techniques avancés. o Compétences : Expertise technique, capacité à résoudre des problèmes complexes. o Rôles : Technicien Support Niveau 2 | R22: ='ERP2'!$C$36 -> Holding : ETP dédiés : 3 Filiale : ETP dédiés : 1 | S22: ='ERP2'!$C$48 -> Oui
B23: =SUM(Achats!$E$7:$E$59)/COUNT(Achats!$E$7:$E$59) -> 1 | D23: oui | E23: =IF(Achats!$C$7="Non prévu",Achats!$C$7,Achats!$C$9) -> COFIFED | F23: =IF(Achats!$C$7="Développement interne","COFINA",Achats!$C$8) -> COFINA | G23: =Achats!$C$14 -> Moyen | H23: =Achats!$C$10 -> 1.1 | I23: =Achats!$C$11 -> 1.2 | J23: =LEFT(Achats!$C$34,3) -> NON | K23: =Achats!$C$41 -> On-site | L23: =Achats!$C$24 -> Illimité | M23: =Achats!$C$28 -> NON | N23: =Achats!$C$29 -> NON | O23: =Achats!$C$19 -> Moyen | P23: =Achats!$C$55 -> Oui | Q23: =Achats!$C$35 -> Niveau 1: Filiale : ETP dédiés : 3 Niveau 2 : Filiale : ETP dédiés : 3 Niveau 3 : Filiale d'ETP : 3 | R23: =Achats!$C$36 -> Filiale : ETP dédiés : 3 | S23: =Achats!$C$48 -> Non
B24: =SUM(GC!$E$7:$E$59)/COUNT(GC!$E$7:$E$59) -> 1 | D24: oui | E24: =IF(GC!$C$7="Non prévu",GC!$C$7,GC!$C$9) -> application de recrutement RH & gestion des contrats | F24: =IF(GC!$C$7="Développement interne","COFINA",GC!$C$8) -> COFINA | G24: =GC!$C$14 -> Moyen | H24: =GC!$C$10 -> 1.0 | I24: =GC!$C$11 -> 1.0 | J24: =LEFT(GC!$C$34,3) -> Non | K24: =GC!$C$41 -> On-site | L24: =GC!$C$24 -> Illimité | M24: =GC!$C$28 -> NON | N24: =GC!$C$29 -> NON | O24: =GC!$C$19 -> Très haut | P24: =GC!$C$55 -> Non | Q24: =GC!$C$35 -> Niveau 1: Holding : ETP dédiés : 3 Niveau 2 : Filiale : ETP dédiés : 3 GROUPE | R24: =GC!$C$36 -> Holding : ETP dédiés : 3 Filiale : ETP dédiés : 1 | S24: =GC!$C$48 -> Non
B25: =SUM(Mail!$E$7:$E$42)/COUNT(Mail!$E$7:$E$42) -> 1 | D25: oui | E25: =IF(Mail!$C$7="Non prévu",Mail!$C$7,Mail!$C$9) -> OFFICE 365 | F25: =IF(Mail!$C$7="Développement interne","COFINA",Mail!$C$8) -> Microsoft | G25: =Mail!$C$17 -> Primoridal | H25: =Mail!$C$10 -> NA | I25: =Mail!$C$11 -> NA | J25: =LEFT(Mail!$C$28,3) -> Non | K25: =Mail!$C$12 -> Cloud | M25: =Mail!$C$25 -> NA | P25: =Mail!$C$38 -> Non | Q25: =Mail!$C$29 -> N1 & 2 | S25: =Mail!$C$33 -> Oui
B26: =Others!E177 -> 0.96969697 | D26: =Others!F177 -> 1
B27: =IT!E93 -> 1 | D27: oui

Sheet QG
A1: Retour à la page d'accueil
A2: Questions génériques IT | B2: =C136 -> 1 | D2: Complément
A3: Global | B3: Réponse, détail et/ou fichier fourni | C3: Eval | D3: Document à fournir | F3: NB Pour les questions concernant l’audit de l’existant IT, veuillez prendre en compte les réponses écrites en orange
A4: est-ce que vous avez mis en place la stratégie IT ? Découle-t-elle de la stratégie de l'entreprise ? Si oui, pouvez-vous les partager? | B4: Stratégie d'Entreprise : Notre vision : Etre le modèle panafricain de la finance inclusive. Notre mission : Créer de la valeur ajoutée pour nos partenaires et participer durablement au développement du continent africain. Stratégie IT Vision IT : Votre rêve devient notre mission Stratégie IT La vision de COFINA TOGO s’inscrit dans la stratégie IT du groupe COFINA. En effet le groupe a pour ambition à l’horizon 2025 d’avoir : • Un SI centralisé et sécurité • Une automatisation des 80% de des taches de la filiale • Une démocratisation de l’information à travers un BI (Business Intelligence) self-service • Un IT « As à profit Center » : l’IT serait un centre de profit et non un centre de cout | C4: =IF(TRIM(B4)="",0,1) -> 1 | D4: voir le schéma directeur
A5: Pouvez-vous présenter l'organisation IT ? Pouvez-vous fournir un organigramme détaillé (départements, sections, groupes, équipes, etc.) des divisions informatiques comprenant des informations sur les effectifs et les responsabilités (en spécifiant: interne, prestataire, temporaire, stagiaire, vacant) | B5: Organisation IT 1. Responsable du département Informatique Responsable informatique Filiale  Effectif : 1 (interne)  Responsabilités : Supervision générale de toutes les opérations informatiques, définition de la stratégie IT, gestion des budgets, collaboration avec la direction générale.  Définition et mise en œuvre des politiques de sécurité, gestion des risques, surveillance des systèmes pour détecter les intrusions.  Analyse des vulnérabilités, réponse aux incidents de sécurité, audits de sécurité réguliers.  Garantir la Confidentialité, l’Intégrité, la Disponibilité et la Sécurité du système  d’information de l’institution et assurer les évolutions technologiques afin de satisfaire la clientèle interne et externe.  Faciliter l’utilisation du matériel informatique, des outils bureautiques et des logiciels mis à la disposition des utilisateurs  Veiller à leur bon fonctionnement et à leur meilleure exploitation, dans les délais requis afin de réduire au maximum les interruptions de services et contribuer ainsi à la  réalisation de la production de l’Entreprise.  Assurer le bon fonctionnement de la base de données et la disponibilité des informations 2. Administrateur des Systèmes et Réseaux Effectif : vacant  Responsabilités : Supervision de l'infrastructure réseau et des systèmes, gestion des projets de mise à jour et de maintenance.  Configuration et maintenance des serveurs, des réseaux, résolution des problèmes techniques, sécurité des systèmes.  Support technique de niveau 1, assistance aux administrateurs, maintenance de base des équipements. 3. Assistant Systèmes et Réseaux :  Effectif : 1 (interne) - Dépanner et configurer le matériel informatique dans les délais requis, afin que les utilisateurs disposent de leur équipement en bon état tout en respectant les SLA définis ; - Aider et former les utilisateurs à une bonne exploitation du matériel informatique et des outils bureautiques afin d’augmenter la production de l’entreprise ; - Organiser et fournir des statistiques sur la gestion du matériel informatique en panne afin de prévenir les éventuelles interruptions de service des utilisateurs. 4. Administrateur des Bases de Données et Développement Applicatif Effectif : vacant  Responsabilités : Gestion des bases de données, supervision des projets de développement, coordination avec les autres départements.  Installation, configuration et maintenance des bases de données, optimisation des performances, sauvegarde et récupération.  Développement et maintenance des applications internes, développement de nouvelles fonctionnalités, correction de bugs.  Support aux administrateurs et aux développeurs, tâches de développement de base, gestion des données.  Supervision de l'équipe de support, gestion des incidents et des demandes des utilisateurs.  Assistance technique aux utilisateurs, résolution des incidents, formation des utilisateurs. 5. Assistant base de données :  Effectif : 2 (interne) Responsabilités : Assurer l’administration des bases de données Oracle afin de garantir une disponibilité maximale des applications aux utilisateurs. - Encadrer et superviser les activités du service Exploitation afin de garantir aux utilisateurs le taux de disponibilité prévu. - Superviser les activités de paramétrage afin garantir un fonctionnement optimal de l’applicatif bancaire conforme aux exigences du métier | C5: =IF(TRIM(B5)="",0,1) -> 1 | D5: Oui
A6: Pouvez-vous me partager les fiches de postes (pour chaque poste figurant sur l'organigramme IT) ? | B6: oui | C6: =IF(TRIM(B6)="",0,1) -> 1 | D6: Oui
A7: Est-ce qu'il y a des fonctions ou activités qui sont entièrement ou partiellement externalisées à des sous-traitants ou des partenaires (par exemple, gestion des installations pour les centres de données, service d'assistance informatique, opérations de certaines applications ou infrastructures, ADM dans certains domaines d'application), ...? | B7: oui | C7: =IF(TRIM(B7)="",0,1) -> 1 | D7: installation des nouveaux systèmes de sécurité électronique (contrôle d'accès, système incendie, anti-intrusion) et de vidéo surveillance
A8: Quel était le Turnover en 2023 ? | B8: nous n'avons enregistré aucun départ de collaborateurs durant cette période | C8: =IF(TRIM(B8)="",0,1) -> 1 | D8: Oui
A9: Avez-vous mis en place un schéma directeur IT? Si oui, pouvez-vous le partager? | B9: oui | C9: =IF(TRIM(B9)="",0,1) -> 1 | D9: Oui
A10: Quelles sont les principales améliorations informatiques attendues de la part de la communauté des utilisateurs métiers ? Exemples: · TTM plus court · Performances des services alignées sur les performances de l'entreprise · Amélioration mesurable du service basée sur des KPI convenus · Compétences améliorées en informatique pour mieux comprendre les exigences de l'entreprise et les traduire en solutions informatiques · Gestion de la demande simplifiée et efficace | B10: Automatisation des processus / Analytique avancée et reporting / Intégration et interopérabilité/ Simplicité d'utilisation:voici l’approche détaillée : Automatisation des Processus : • Plan : Développer des applications pour automatiser les processus clés tels que la gestion des stocks, la gestion des ventes, la gestion des conventions de crédit, et les processus de recrutement, etc. • Timing : Courant de l'année 2024. • Budget : Développement local. Analytique Avancée et Reporting : • Plan : Mise en place d'une plateforme analytique centralisée utilisant des outils comme Power BI ou Tableau pour visualiser et analyser les données opérationnelles et financières. • Timing : 2025. • Budget : À définir. Intégration et Interopérabilité : • Plan : Intégration entre les systèmes Oracle Flexcube et les plateformes de nos différents partenaires tels que Togocom (projet bank to wallet), GTP (pour les cartes VISA), l’application mobile, etc. • Timing : Déploiements itératifs sur les 2 prochains mois | C10: =IF(TRIM(B10)="",0,1) -> 1 | D10: Pouvez-vous détailler comment avez-vous prévu de le faire et quand? Quel est le budget validé pour ces initiatives?
A11: Quelles sont les principales améliorations IT identifiées par la communauté IT? Exemples: · Harmonisation de l'architecture · Gestion simplifiée des fournisseurs · Harmonisation du contrat de support · Rareté des ressources qualifiées · Gestion des incidents · Demandes de service standardisées · Mesures visant à améliorer la disponibilité des services, telles que - Améliorer la gestion des pannes et des performances - Introduire des outils de gestion des services IT - Standardiser les processus - Mettre à jour la documentation - Restructurer lorganisation IT - Consolider les centres de données et les centres d'opérations | B11: Automatisation et IA: L'automatisation des processus IT et l'intégration de l'intelligence artificielle pour améliorer l'efficacité opérationnelle. Sécurité renforcée: Des technologies avancées pour protéger les données et les infrastructures contre les cybermenaces croissantes. Cloud computing: L'adoption accrue des services cloud pour la flexibilité, l'évolutivité et la réduction des coûts. IoT (Internet des Objets): L'utilisation croissante des appareils connectés pour collecter des données et optimiser les processus. Blockchain: L'exploration des applications de la technologie blockchain pour la sécurisation des transactions et des contrats. Analyse des données avancée: Utilisation de l'analyse prédictive et du big data pour prendre des décisions plus éclairées. Expérience utilisateur améliorée | C11: =IF(TRIM(B11)="",0,1) -> 1 | D11: Pouvez-vous détailler comment avez-vous prévu de le faire et quand? Quel est le budget validé pour ces initiatives?
A12: Applications | B12: Réponse, détail et/ou fichier fourni | D12: Document à fournir
A13: Pouvez-vous montrer l'architecture informatique actuelle prenant en charge l'ensemble de l'activité (interne et externe) ？ | B13: oui | C13: =IF(TRIM(B13)="",0,1) -> 1 | D13: Non
A14: Est-ce que les applications sont centralisées pour toutes les filiales ou chaque filiale à son propre SI ou s'agit-il d'une combinaison des 2? | B14: NON | C14: =IF(TRIM(B14)="",0,1) -> 1 | D14: Non
A15: Est-ce que vous disposez d'une cartographie des applications existantes? Par filiale? | B15: oui | C15: =IF(TRIM(B15)="",0,1) -> 1 | D15: Non
A16: Existe-t-il une stratégie d’architecture d’application commune interfiliale mise en œuvre/prévu ? si oui: - quels composants d'application font partie des plans - à quel niveau l'harmonisation des composants est-elle atteinte o fournisseur et logiciel uniquement o version du système o configuration et customisation du système o système centralisé avec configuration multi-tenant | B16: NON | C16: =IF(TRIM(B16)="",0,1) -> 1 | D16: Non
A17: Si oui, est-ce qu'elle spécifie bien ce qui est fournis par des prestataires externes de ce qui est développé en interne? | B17: NA | C17: =IF(TRIM(B17)="",0,1) -> 1 | D17: Non
A18: Pour les les solutions qui ont été développées en interne, quelle language a été utilisé ? et pourquoi? | B18: Les langages utilisés pour le développement de nos applications internes sont PHP avec le framework Laravel combiné avec du Vue JS.Nous avons préféré utiliser PHP avec le framework Laravel parceque ce dernier est un framework backend qui se distingue par sa documentation exhaustive, sa communauté active, ses migrations de base de données robustes, son ORM Eloquent, ses fonctionnalités de sécurité intégrées, ses outils de tests automatisés, sa facilité d'intégration de services tiers, son outil en ligne de commande Artisan, sa gestion efficace des dépendances, son système de routage flexible et son moteur de template Blade, en faisant un choix idéal pour le développement d'applications web de toute envergure. | C18: =IF(TRIM(B18)="",0,1) -> 1 | D18: Pourquoi?
A19: Avez-vous un cadre de développement ? | B19: Choisir Laravel pour le backend et Vue.js pour le frontend permet de bénéficier d'un développement web moderne et efficace, avec une gestion simplifiée de l'authentification et des ORM, à la réactivité des composants réutilisables. En ce qui concerne l'utilisation de Vue.JS en frontend, c'est est un framework JavaScript qui se distingue par sa flexibilité, son intégration facile avec d'autres projets ou bibliothèques, sa réactivité grâce à son système de liaison de données bidirectionnelle, sa capacité à créer des composants réutilisables, son écosystème riche avec des outils comme Vue CLI et Vuex, et sa forte communauté de développeurs, en faisant un choix idéal pour le développement d'interfaces utilisateur dynamiques et modernes. | C19: =IF(TRIM(B19)="",0,1) -> 1 | D19: Pourquoi?
A20: Quelle est la taille de l’équipe de développement ? | B20: L'équipe de developpement est composée de 3 personnes (les deux assistants et moi-même ) | C20: =IF(TRIM(B20)="",0,1) -> 1 | D20: Ce n'est pas ce qui apparait sur l'organigramme
A21: Est-ce que vous avez une documentation? Si oui, est-elle à jour? | B21: OUI | C21: =IF(TRIM(B21)="",0,1) -> 1 | D21: Pouvez-vous partager un exemple ou 2?
A22: Qui assure le support des outils internes ? | B22: Le support des outils internes est assuré par IT LOCAL | C22: =IF(TRIM(B22)="",0,1) -> 1 | D22: Oui
A23: Comment gérez-vous le versioning ? Avez-vous une feuille de route ? | B23: Le versionning est géré par Git et Github | C23: =IF(TRIM(B23)="",0,1) -> 1 | D23: Oui
A24: Contractualisation | B24: Réponse, détail et/ou fichier fourni | D24: Document à fournir
A25: Est-ce que vous avez des contrats de support avec tous les prestataires IT? | B25: NON Pour certains systèmes, nous avons préféré gérer le support et la maintenance préventive et curative en local afin d'économiser au niveau de la filiale, car nous venions de débuter l'activité. Cependant, nous prévoyons de signer un contrat de maintenance avec des prestataires d'ici décembre 2024 | C25: =IF(TRIM(B25)="",0,1) -> 1 | D25: Pourquoi?
A26: Est-ce que les contrats existants incluent des SLA? Pourvez-vous me les partager? | B26: NON | C26: =IF(TRIM(B26)="",0,1) -> 1 | D26: Pouvez-vous les partager ?
A27: Infrastructure | B27: Réponse, détail et/ou fichier fourni | D27: Document à fournir
A28: Pouvez-vous partager l'architecture du réseau ? | B28: oui | C28: =IF(TRIM(B28)="",0,1) -> 1 | D28: Non
A29: Est-ce que vous utilisez exclusivement des infrastructures sur le Cloud ou sur site ou un mix des 2 ? | B29: MIX DES DEUX | D29: Non
A30: Si vous utilisez des infrastructures sur le Cloud, s'agit-il de Cloud public, lequel ? ou privé ? | B30: Voir IT GROUPE | D30: Non
A31: Si vous utilisez des infrastructures sur site, l'IT est propriétaire de son (ou ses) centre de données ou utilisez-vous un datacenter partagé ? Précisez lesquels et les infra installés | B31: Pour les datacenters à Abidjan ou Dakar, le local est partagées mais en filiale Nous utilisons des infrastructures sur site pour notre IT. Nous ne possédons pas de centre de données dédié, mais nous gérons nos propres serveurs dans notre environnement local. Cela inclut un serveur physique Cisco UCS C220 M5SX qui héberge plusieurs machines virtuelles Windows Server et Linux, ainsi que d'autres infrastructures réseau comme notre firewall Fortinet et notre réseau VLAN segmenté. | D31: Non
A32: Envisagez-vous de grands changements dans le Datacenter ? Si oui, quoi et quand ? | B32: Voir IT GROUPE | C32: =IF(TRIM(B32)="",0,1) -> 1 | D32: Non
A33: Quels sont les liens existants et leurs bandes passantes ? | B33: notre siège dispose d'une liaison principale de 50 Mo avec une liaison de backup de 10 Mo via un autre FAI. Pour les agences, nous avons une liaison principale de 10 Mo en fibre optique, avec des modems 4G+ d'un autre opérateur assurant le backup en cas d'interruption de la liaison principale | C33: =IF(TRIM(B33)="",0,1) -> 1 | D33: Peux-tu décrie les lien du siège et des agences, principaux et secondaires?
A34: Existe-t-il des stratégies d’architecture matérielle commune interfiliale mis en œuvre/prévu ? si oui - quels composants font partie des plans - jusqu'où niveau l'harmonisation des composants est-elle atteinte o fournisseur et type de matériel uniquement o Version du système d'exploitation/base de données o configuration du système telle que la configuration de la virtualisation o système centralisé hébergeant plusieurs applications utilisées par les pays | B34: oui type de matériel uniquement o Version du système d'exploitation/base de données o configuration du système telle que la configuration de la virtualisation o système centralisé hébergeant plusieurs applications utilisées par les pays | C34: =IF(TRIM(B34)="",0,1) -> 1 | D34: malheureusement ça n'a pas été formalisé.
A35: Veuillez fournir une liste de serveurs existants, de systèmes d'exploitation et de fournisseurs ? | B35: ESXI CISCO/HYPERVISEUR VMWARE 7.0 Update 1/ SYROAD/EN LOCALE | C35: =IF(TRIM(B35)="",0,1) -> 1 | D35: Non
A36: Veuillez fournir des informations sur les éléments de stockage et leur configuration opérationnelle, par ex. NAS, SAN? | B36: oui Nous effectuons des sauvegardes journalières sur un ordinateur avec un disque dur de 24 To. Le premier jour de chaque mois, nous copions les données du mois précédent pour les externaliser dans un autre site au sein de nos agences. Cela nous permet de récupérer les données en cas de défaillance du serveur de sauvegarde. | C36: =IF(TRIM(B36)="",0,1) -> 1 | D36: Non
A37: Veuillez fournir une liste des équipements réseaux dans l'environnement LAN/WAN, par ex. routeurs, pare-feu | B37: ROUTEUR CISCO/ Cisco IOS/ SYROAD/EN LOCALE FIREWALL FORTINET/FortiOS/ SYROAD/EN LOCALE APFORTINET/FortiOS/ SYROAD/EN LOCALE SWITCH CISCO/Cisco IOS / SYROAD/ EN LOCALE | C37: =IF(TRIM(B37)="",0,1) -> 1 | D37: Non
A38: Veuillez mentionner l'emplacement physique des équipements IT ci-dessus dans les centres de données? | B38: La majorité de nos équipements, réseaux et systèmes se trouvent dans un local IT au siège. Ce local respecte tous les normes ISO 27001 à l'exception de la protection contre les incendies, un point que nous prévoyons de corriger d'ici le 31 janvier 2025. | C38: =IF(TRIM(B38)="",0,1) -> 1 | D38: Non
A39: Est-ce que tous ces équipements sont supervisés à distance? | B39: NON | C39: =IF(TRIM(B39)="",0,1) -> 1 | D39: Non
A40: Est-ce que vous faites des maintenances préventive? Sur quel système et à quelle fréquence? | B40: oui tous les trois mois | C40: =IF(TRIM(B40)="",0,1) -> 1 | D40: Non
...

Sheet Secu
A1: Retour à la page d'accueil
A2: Questions Sécurité | B2: =C51 -> 1 | D2: Complément
A3: Sécurité de l’information - Information et documentation à fournir | B3: Réponse, détail et/ou fichier fourni | C3: Eval | D3: Questions complémentaires
A4: Quels systèmes, procédures ou pratiques de sécurité sont en place pour protéger les systèmes d’information ? | B4: Kaspersky Advanced, EDR Kaspersky, SIEM Qradar, Qualys, SOC, Fortinet,IPS et IDS | C4: =IF(TRIM(A4)="","",IF(TRIM(B4)="",0,1)) -> 1 | D4: Qu'en est-il des procédures et politiques?
A5: Existe-t-il des restrictions légales concernant le traitement des données par d'autres parties que le client ? Toute limitation pour l'accès à distance aux systèmes, les opérations à distance des systèmes | B5: oui | C5: =IF(TRIM(A5)="","",IF(TRIM(B5)="",0,1)) -> 1 | D5: Détailler
A6: Existe-t-il des plans de reprise après sinistre et de continuité des activités ? | B6: oui | C6: =IF(TRIM(A6)="","",IF(TRIM(B6)="",0,1)) -> 1 | D6: Pouvez-vous les partager?
A7: Existe-t-il une solution de reprise après sinistre (DR) ? | B7: oui Sauvegarde et restauration | C7: =IF(TRIM(A7)="","",IF(TRIM(B7)="",0,1)) -> 1 | D7: Détailler
A8: Sinon, avez-vous au moins des procédures de récupération ? Pour quels services? | B8: oui | C8: =IF(TRIM(A8)="","",IF(TRIM(B8)="",0,1)) -> 1 | D8: Pouvez-vous les partager?
A9: Y a-t-il des politiques de sécurité informatique en place ? | B9: oui | C9: =IF(TRIM(A9)="","",IF(TRIM(B9)="",0,1)) -> 1 | D9: Pouvez-vous les partager?
A10: o Gestion des utilisateurs : | B10: OUI | C10: =IF(TRIM(A10)="","",IF(TRIM(B10)="",0,1)) -> 1 | D10: Questions complémentaires
A11: § La procédure technique concernant la mise à jour des utilisateurs (création / modification / suppression) ; | B11: oui | C11: =IF(TRIM(A11)="","",IF(TRIM(B11)="",0,1)) -> 1 | D11: Pouvez-vous la partager?
A12: § La procédure technique concernant la désactivation / activation utilisateur; | B12: oui | C12: =IF(TRIM(A12)="","",IF(TRIM(B12)="",0,1)) -> 1 | D12: Pouvez-vous la partager?
A13: o Gestion des habilitations : | B13: OUI | C13: =IF(TRIM(A13)="","",IF(TRIM(B13)="",0,1)) -> 1 | D13: Questions complémentaires
A14: § La liste des administrateurs système (y compris comptes administrateurs de domaines). | B14: oui | C14: =IF(TRIM(A14)="","",IF(TRIM(B14)="",0,1)) -> 1 | D14: Pouvez-vous la partager?
A15: § La liste des profils disponibles dans chaque application | B15: oui | C15: =IF(TRIM(A15)="","",IF(TRIM(B15)="",0,1)) -> 1 | D15: Pouvez-vous la partager?
... A22: · Règles d’attribution | B22: oui | C22: =IF(TRIM(A22)="","",IF(TRIM(B22)="",0,1)) -> 1 | D22: Pouvez-vous les partager?
A23: · Durée de vie. | B23: 45 jours | C23: =IF(TRIM(A23)="","",IF(TRIM(B23)="",0,1)) -> 1
A24: · Longueur minimale. | B24: 14 | C24: =IF(TRIM(A24)="","",IF(TRIM(B24)="",0,1)) -> 1
A25: · Complexité. | B25: oui | C25: =IF(TRIM(A25)="","",IF(TRIM(B25)="",0,1)) -> 1
A26: · Blocage après X tentatives de connexions infructueuses. | B26: oui | C26: =IF(TRIM(A26)="","",IF(TRIM(B26)="",0,1)) -> 1
A27: · Historique. | B27: oui | C27: =IF(TRIM(A27)="","",IF(TRIM(B27)="",0,1)) -> 1
A28: · Changement obligatoire du mot de passe d’initialisation. | B28: oui | C28: =IF(TRIM(A28)="","",IF(TRIM(B28)="",0,1)) -> 1
A29: · Durée d’inactivité avant verrouillage de la session. | B29: oui | C29: =IF(TRIM(A29)="","",IF(TRIM(B29)="",0,1)) -> 1
A30: o Antivirus/antimaleware : | B30: OUI | C30: =IF(TRIM(A30)="","",IF(TRIM(B30)="",0,1)) -> 1 | D30: Questions complémentaires
A31: § Les copies d’écrans des versions d’antivirus/antimaleware installées sur les serveurs | B31: oui | C31: =IF(TRIM(A31)="","",IF(TRIM(B31)="",0,1)) -> 1 | D31: Pouvez-vous les partager?
A32: § Une copie d’écran de la version d’antivirus/antimaleware installée sur un poste de travail. | B32: oui | C32: =IF(TRIM(A32)="","",IF(TRIM(B32)="",0,1)) -> 1 | D32: Pouvez-vous les partager?
A33: o Sauvegardes : | B33: OUI | C33: =IF(TRIM(A33)="","",IF(TRIM(B33)="",0,1)) -> 1 | D33: Questions complémentaires
A34: § La politique de sauvegarde des données informatiques, incluant les procédures de restauration et d’archivage ; | B34: oui | C34: =IF(TRIM(A34)="","",IF(TRIM(B34)="",0,1)) -> 1 | D34: Pouvez-vous la partager?
A35: § Le planning des sauvegardes ; | B35: oui | C35: =IF(TRIM(A35)="","",IF(TRIM(B35)="",0,1)) -> 1 | D35: Pourquoi?
A36: Sécurité physique et accès au(x) site(s) | B36: Réponse, détail et/ou fichier fourni | D36: Questions complémentaires
A37: Décrire la manière dont l'accès aux bureaux est organisé (badges nominatifs, empreintes digitales, photos, …) | B37: badges | C37: =IF(TRIM(A37)="","",IF(TRIM(B37)="",0,1)) -> 1 | D37: Non
A38: Décrire les installations qui hébergent actuellement l'organisation des opérations : Emplacement(s), taille(s), Type (centre de données, centre d'opérations central, centre d'opérations local, etc.), Propriété (loué-en leasing-propriétaire), … | B38: centre d'opérations local | C38: =IF(TRIM(A38)="","",IF(TRIM(B38)="",0,1)) -> 1 | D38: Non
A39: Fournir des informations sur la manière dont l'accès aux sites des centres de données est organisé | B39: badges | C39: =IF(TRIM(A39)="","",IF(TRIM(B39)="",0,1)) -> 1 | D39: Non
A40: Existe-t-il des restrictions d'accès (24h/24 et 7j/7) aux sites des centres de données | B40: oui l'accès aux centres de données est restreint et soumis à des politiques strictes de sécurité et d'accès. Contrôle d'accès physique / Horaires d'accès / Autorisations préalables : L'accès peut nécessiter une autorisation préalable et être strictement réservé au personnel autorisé ou aux techniciens en cas d'intervention d'urgence / Surveillance continue | C40: =IF(TRIM(A40)="","",IF(TRIM(B40)="",0,1)) -> 1 | D40: Lesquels?
A41: Existe-t-il un Data Center de secours? Si oui, suit-il des restrictions? Lesquels? | B41: oui | C41: =IF(TRIM(A41)="","",IF(TRIM(B41)="",0,1)) -> 1 | D41: Détails
A42: Outils de sécurité | B42: Réponse, détail et/ou fichier fourni | D42: Questions complémentaires
A43: Pouvez-vous lister de sécurité mis en place et décrires brièvement leurs fonctionnalités dans la colonne détails (gestion des mdp, gestion des logs, IAM, DLP, antimaleware, SASE, …) ? | B43: en dehors de la gestion des mots de passe et de l'Antivirus (Kaspersky Advanced, EDR Kaspersky), les autres dispositifs de sécurité sont gérés au niveau de l'IT groupe : Firewall : Fortinet avec IDS/IPS activé. SOC : Supervision 24/7 des actifs du groupe COFINA pour prévenir toute cyberattaque. SIEM : Qradar, Qualys. | C43: =IF(TRIM(A43)="","",IF(TRIM(B43)="",0,1)) -> 1 | D43: Pourquoi?
A44: Veuillez préciser pour chaque outil s'il est installé sur site ou utilisé à partir du Cloud (SaaS) ? | B44: SITE | C44: =IF(TRIM(A44)="","",IF(TRIM(B44)="",0,1)) -> 1 | D44: Pourquoi?
A45: Quelle est la criticité de chaque outil ? | B45: Firewall Fortinet avec IDS/IPS activé : Criticité : Très élevée Raison : Le firewall Fortinet avec IDS/IPS joue un rôle crucial en sécurisant le périmètre réseau, en détectant et en prévenant les intrusions potentielles. Il est essentiel pour protéger vos systèmes contre les attaques externes et internes. SOC (Security Operations Center) : Criticité : Élevée Raison : Le SOC est responsable de la surveillance continue de vos actifs informatiques, détectant les menaces et répondant aux incidents de sécurité en temps réel. Il contribue à minimiser les risques de cyberattaques et à assurer la résilience de votre infrastructure. SIEM (Security Information and Event Management) - Qradar, Qualys : Criticité : Élevée Raison : Le SIEM est crucial pour la collecte, la corrélation et l'analyse des événements de sécurité à travers votre réseau. Qradar et Qualys fournissent des capacités avancées de gestion des informations de sécurité, aidant à identifier les menaces potentielles et à répondre aux incidents de manière proactive. | C45: =IF(TRIM(A45)="","",IF(TRIM(B45)="",0,1)) -> 1 | D45: Pourquoi?
A46: Quel est le nombre actuel de licences détenues par la filiale pour chaque outil ? | B46: voir IT groupe | C46: =IF(TRIM(A46)="","",IF(TRIM(B46)="",0,1)) -> 1 | D46: Pourquoi?
...

Sheet Contracts
A1: Retour à la page d'accueil
A2: # | B2: Nom du fichier | C2: Lien du fichier | D2: Prestataire | E2: Bénéficiaire | F2: Scope (périmètre, solution, modules/ services inclus, etc.) | G2: [L]icences [S]ouscription [I]mplémentation [M]aintenance/Support | H2: Volume (# licences, # souscriptions, …) | I2: Coût | J2: Mécanisme de coût | K2: Importance (haute / moyenne / faible) | L2: Date de début | M2: Durée du contrat | N2: SLA (dispo ou pas) et lien | O2: Notification de résiliation | P2: Contrat signé par les 2 parties (oui/non) | Q2: Remise appliquée | R2: Responsable Achat | S2: Commentaires / Information complémentaire / Questions à poser
A3: 1 | B3: INFOGERANCE | C3: NA | D3: CANOPUS | E3: COFINA TOGO | F3: LOCATION D'IMPRIMANTE | G3: NA | H3: NA | I3: 7380000 | K3: moyenne | L3: 2022 | N3: NA | O3: 2 mois | P3: OUI | Q3: N/A | R3: Amadou Mar DIOP
A4: 2 | B4: FAI | C4: NA | D4: GVA | E4: COFINA TOGO | F4: INTERNET | G4: M | H4: NA | I4: 13200000 | K4: haute | L4: 2021 | N4: NA | O4: 2 mois | P4: OUI | Q4: N/A | R4: Amadou Mar DIOP
A5: 3 | B5: FAI | C5: NA | D5: TOGOCOM | E5: COFINA TOGO | F5: INTERNET | G5: M | H5: NA | I5: 5436000 | K5: haute | L5: 2021 | N5: NA | O5: 2 mois | P5: OUI | Q5: N/A | R5: Amadou Mar DIOP
A6: 4 | B6: GOMISE | C6: NA | D6: CAGECFI | E6: COFINA TOGO | F6: PAIE | G6: M | H6: NA | I6: 593000 | K6: haute | L6: 2021 | N6: NA | O6: 2 mois | P6: OUI | Q6: N/A | R6: IT GROUPE
A7: 5 | B7: MOBILE | C7: NA | D7: Smarts Solutions Managers | E7: COFINA TOGO | F7: COFINA MOBILE + | G7: M | H7: NA | I7: VOIR IT GROUPE | K7: haute | L7: 2024 | M7: NA | N7: NA | O7: 2 mois | P7: OUI | Q7: N/A | R7: IT GROUPE
A8: 6 | B8: IMMO | C8: NA | D8: MEDIASOFT | E8: COFINA TOGO | F8: IMMOBILISATION DES BIEN ET ACTIFS | G8: L | H8: NA | I8: 4200000 | K8: haute | L8: 2023 | N8: NA | O8: 2 mois | P8: OUI | Q8: N/A | R8: DIRECTION
A9: 7 | B9: FLEXCUBE | C9: NA | D9: JMR Infotech | E9: COFINA TOGO | F9: SYSTÈME D'INFORMATION | G9: M | H9: NA | I9: VOIR IT GROUPE | K9: haute | L9: 2024 | M9: NA | N9: NA | O9: 2 mois | P9: OUI | Q9: N/A | R9: IT GROUPE
A10: 8
A11: 9
A12: 10
A13: 11
A14: 12
A15: 13
A16: 14
A17: 15
A18: 16
A19: 17
A20: 18
A21: 19
... A72: 70
A123: Combien de ces demandes surviennent en moyenne par an ?

Sheet ✅ Projets 2026
A1: Retour à la page d'accueil
B2: Projet | C2: Objectif | D2: État Actuel | E2: Progrès Réalisé (%) | F2: Résultats et Avantages | G2: Commentaire
B3: Présentation Projets Informatiques Accomplis 2025
A4: 1 | B4: Digitalisation des processus arrêt de caisse | C4: Automatiser et simplifier les processus de clôture de caisse | D4: Processus automatisés, réduction du temps | E4: 1 | F4: - Gain de temps.
F5: - Minimisation des erreurs humaines.
A6: 3 | B6: Application de rappel des échéances (15j, 7j, J) | C6: Optimiser la gestion des échéances pour éviter les retards | D6: Application fonctionnelle, rappels envoyés | E6: 1 | F6: - Réduction des retards de paiement.
F7: - Amélioration de la trésorerie.
A8: 5 | B8: Logiciel de Gestion du Parc Informatique & Helpdesk COFIHELP | C8: Améliorer la gestion du parc & le support technique | D8: Système opérationnel | E8: 1 | F8: - Réduction des pannes.
F9: - Productivité accrue.
A10: 6 | D10: Correctifs appliqués | E10: 1 | F10: - Stabilité et sécurité renforcées.
A11: 7 | D11: Transactions opérationnelles | E11: 0.9 | F11: - Fluidité des paiements.
F12: - Plus de choix pour les clients.
A13: 8 | B13: Digitalisation des conventions de crédit | C13: Accélérer le traitement des contrats de crédit | D13: Projet terminé | E13: 1 | F13: - Réduction des délais de traitement.
F14: - Meilleure traçabilité , Minimisation des erreurs humaines
A15: 9 | B15: Automatisation des extractions opérationnelles Flexcube REPORT | C15: Gagner du temps sur la génération de rapports | D15: Extractions automatisées | E15: 1 | F15: - Moins de charge manuelle.
F16: - Rapports disponibles rapidement.
A17: 11 | B17: Application de gestion des COFICARTES | C17: Suivre les ventes et le stock de cartes VISA | D17: Application opérationnelle | E17: 1 | F17: - Suivi en temps réel.
F18: - Traçabilité améliorée.
A19: 12 | B19: Application Recrutement RH | C19: Améliorer le processus de recrutement | D19: Application fonctionnelle | E19: 0.8 | F19: - Processus fluidifié.
A20: 14 | B20: IMMO – Gestion des immobilisations | C20: Suivre les immobilisations de l'entreprise | D20: Application fonctionnelle | E20: 1 | F20: - Meilleure visibilité patrimoniale.
A21: 15 | B21: COFIGED – Archivage numérique | C21: Digitaliser l’archivage des documents | D21: Application déployée | E21: 1 | F21: - Réduction du papier.
F22: - Accès rapide aux documents.
A23: 16 | B23: GESTION DE STOCK (Parc IT, consommables…) | C23: Optimiser le suivi des stocks | D23: Application en production | E23: 1 | F23: - Traçabilité complète.
A24: 18 | B24: Implémentation Carthago (réglementaire) | C24: Assurer la conformité réglementaire | D24: Système en production | E24: 1 | F24: - Conformité assurée.
F25: - Risques réglementaires réduits.
A26: 19 | B26: Application d’Intégration Automatique des OD | C26: Simplifier les opérations comptables | D26: Application en service | E26: 1 | F26: - Rapidité et fiabilité des OD.
A27: 20 | B27: COFINA MOBILE+ | C27: Cofina Mobile+ est une application web et mobile , permettant aux clients d'accéder à des services bancaires à distance 24h/24 et 7j/7 depuis un ordinateur, une tablette ou un smartphone. | D27: Déployé et opérationnel | E27: 1 | F27: - Disponibilité permanente des services
F28: - Réduction de l'affluence en agence
F29: - Amélioration de l’expérience utilisateur
F30: - Extension de la portée des services bancaires
A31: 21 | B31: SMS Banking | C31: Le service SMS Banking permet aux clients de recevoir des notifications par SMS en temps réel pour chaque mouvement effectué sur leur compte bancaire. Ce service vise à renforcer la transparence et la sécurité des transactions tout en offrant aux clients un suivi instantané de leurs opérations financières. | D31: Déployé et opérationnel | E31: 1 | F31: - Transparence accrue
F32: - Suivi en temps réel des opérations
F33: - Renforcement de la sécurité des comptes
A35: 22 | B35: B2W/W2B | C35: Le projet B2W (Bank to Wallet) / W2B (Wallet to Bank) vise à mettre en place un service permettant aux clients de transférer des fonds entre leurs comptes bancaires et leurs portefeuilles mobiles via un canal USSD. | D35: En phase finale de tests et intégrations | E35: 0.9 | F35: - Accessibilité pour les utilisateurs sans smartphone
F36: - Inclusion financière renforcée
F37: - Réduction des délais de transfert
A39: 23 | B39: Outil de suivi des commissions et digitalisation des workflows | C39: L'Outil de suivi des commissions et digitalisation des workflows vise à améliorer la gestion et le suivi des commissions prelevées en agence et par les équipes back-office. Il intègre une automatisation des processus de validation et de traitement afin d'optimiser l'efficacité opérationnelle et la transparence dans le calcul et le paiement des commissions | D39: Déployé et en production | E39: 1 | F39: - Meilleure visibilité sur les commissions
F40: - Automatisation des validations
F41: - Fiabilité accrue des calculs
F42: - Gains de temps significatifs
...

Sheet CofiDesk
A2: Priorité | B2: Projet | C2: Objectif | E2: Progrès réalisé | F2: Résultats & Avantages | G2: Owner | H2: Start Date | I2: End Date | J2: Date de livraison
A3: 5 | B3: Digitalisation des processus d’arrêt de caisse (ecart de caisse) | C3: Automatiser et simplifier les processus de clôture de caisse | D3: Not Star | F3: - Gain de temps significatif | G3: BABACAR | H3: À définir | I3: À définir | J3: À définir
F4: - Minimisation des erreurs humaines
A5: 7 | B5: ERB – État de Rapprochement Bancaire | C5: Automatiser le rapprochement bancaire | D5: Not Star | F5: - Meilleure traçabilité | G5: À définir | H5: À définir | I5: À définir | J5: À définir
F6: - Réduction des écarts et erreurs humaines
A7: 4 | B7: Application de gestion des COFICARTES | C7: Assurer le suivi des ventes et du stock de cartes VISA | D7: In Progress | F7: - Suivi en temps réel | G7: MAR | H7: — | I7: —
F8: - Traçabilité améliorée
F9: - Réduction des risques réglementaires
A10: 6 | B10: Gestion des pièces comptables – Intégration automatique des OD | C10: Simplifier et fiabiliser les opérations comptables | D10: Not Star | F10: - Rapidité de traitement | G10: MODOU | H10: — | I10: —
F11: Réduire significativement l’impression massive de pièces comptables
F12: archivage
F13: - Fiabilité des écritures comptables
A14: 2 | B14: Digitalisation des conventions de crédit | C14: Accélérer le traitement des contrats de crédit | D14: In Progress | F14: - Meilleure traçabilité | G14: MAR | H14: — | I14: —
F15: - Réduction des erreurs humaines
F16: - Délai de traitement réduit
A17: 1 | B17: Gestion PIP | C17: Optimiser la gestion et le suivi des PIP | D17: In Progress | F17: - Amélioration du suivi opérationnel | G17: MAR | H17: À définir | I17: À définir | J17: À définir
F18: - Données centralisées
A19: 3 | B19: Gestion Fiche Dépense (FED), Petite Caisse & Budget | C19: Digitaliser et contrôler les dépenses internes | D19: In Progress | F19: - Meilleur contrôle budgétaire | G19: MANSOUR | H19: À définir | I19: À définir
F20: - Traçabilité des dépenses
F21: - Réduction des fraudes
B22: Engagements

Sheet PROJETS EN COURS
B1: Priorité | C1: Projet | D1: Objectif | E1: État Actuel | F1: Progrès Réalisé (%) | G1: Résultats et Avantages | H1: Owner | I1: Commentaire
C2: Présentation des Projets Informatiques ENCOURS 2026
A3: 1 | C3: outils de gestion de parc informatique | D3: Centraliser et automatiser le suivi des équipements informatiques (postes, imprimantes, serveurs, etc.) | E3: DONE | F3: 1 | G3: Amélioration du suivi du parc
G4: Réduction des pertes et pannes | H4: BABACAR
A7: 2 | C7: CofiRH | D7: Application RH couvrant : gestion des entretiens d’embauche, gestion des contrats, intranet, communication interne, fiches d’habilitation | E7: DONE | F7: 1 | G7: Centralisation des données RH
G8: - Gestion efficace des habilitations | H8: MODOU/BABACAR
G9: Avance sur salaire
A11: 3 | B11: Priorité 1 | C11: Projet DATA & BI (COFIdash) | D11: Suivi des commissions et pilotage de la performance : PNB & PBT, suivi des objectifs et réalisations | E11: EN COURS | F11: 0.65 | G11: - Décisions basées sur données fiables
G12: - Suivi des performances en temps réel | H12: MODOU/NDICK
A15: 4 | B15: Priorité 2 | C15: Vue Client 360° | D15: Centraliser toutes les informations client issues des différents systèmes (Core Banking, Mobile, Agence, Produits digitaux) dans une interface unique | E15: EN COURS | F15: 0.25 | G15: Vision complète du client
G16: Amélioration de l’expérience client | H16: NDICK/MODOU
A18: 5 | C18: Interopérabilité BCEAO PIP | D18: Assurer une compatibilité avec les systèmes BCEAO pour les transactions. | E18: ENCOURS | F18: 0.98 | G18: - Meilleure conformité réglementaire
G19: - Intégration dans l’écosystème bancaire régional | H19: MAR
G20: - Automatisation des échanges
A21: 6 | B21: Priorité 5 | C21: Cofilcolatte: gestion des garanties | D21: Suivi et gestion des garanties des produits et clients | E21: EN COURS | F21: 0.95 | G21: - Meilleur contrôle des garanties
G22: - Réduction des risques | H22: MANSSOUR
A24: 7 | B24: Priorité 3 | C24: Digitalisation des conventions de crédit | D24: Accélérer le traitement des contrats de crédit | E24: ENCOURS | F24: 0.8 | G24: - Meilleure traçabilité
G25: - Réduction des erreurs humaines | H25: MAR
G26: - Délai de traitement réduit
A27: 8 | B27: Priorité 2 | C27: Gestion Fiche Dépense (FED), Petite Caisse & Budget | D27: Digitaliser et contrôler les dépenses internes | E27: ENCOURS | F27: 0.7 | G27: - Meilleur contrôle budgétaire
G28: - Traçabilité des dépenses | H28: MANSSOUR
G29: - Réduction des fraudes
A30: 9 | C30: Application de gestion des COFICARTES V1 | D30: Assurer le suivi des ventes et du stock de cartes VISA | E30: ENCOURS | F30: 0.9 | G30: - Suivi en temps réel
G31: - Traçabilité améliorée | H31: MAR
G32: - Réduction des risques réglementaires
A33: 10 | C33: Mise en service des équipements de sécurité électronique au niveau des agences.
A36: 10 | C36: Stabilisation de la connexion internet dans les différentes agences
C43: EN COURS+31:48+B43

Sheet CBS
A1: Retour à la page d'accueil | C1: Réponse corrigé à partir du fichier CTI
B2: Core Banking System - Système de Gestion Bancaire
B3: Veuillez répondre à toutes les questions et donner plus de détails (colonne D) lorsque nécessaire, un taux de remplissage est calculé dans le sommaire et devrait être à 100%
B4: Certaines questions peuvent en faire apparaitre de nouvelles auxquelles il faudra répondre, cela entre également dans le calcul du taux de remplissage
B6: Questions | C6: Réponses | D6: Détails | E6: Eval | F6: Complément
B7: COTS ou Développement interne? (Commercial Off-The-Shelf solution) | C7: COTS | E7: =IF(TRIM(B7)="","",IF(TRIM(C7)="",0,1)) -> 1 | F7: Non
B8: =IF(C7="COTS","Nom de l'éditeur","") -> Nom de l'éditeur | C8: Oracle | D8: le produit est directement développé et édité par Oracle Corporation . JMR Infotech, comme partenaire et intégrateur de solutions Oracle. | E8: =IF(TRIM(B8)="","",IF(TRIM(C8)="",0,1)) -> 1 | F8: Non
B9: Nom de la solution | C9: Oracle FLEXCUBE Universal Banking | E9: =IF(TRIM(B9)="","",IF(TRIM(C9)="",0,1)) -> 1 | F9: Non
B10: Quelle est la version/release de l'application ? | C10: Version 14.7 | D10: Version 14.7 | E10: =IF(TRIM(B10)="","",IF(TRIM(C10)="",0,1)) -> 1 | F10: Non
B11: Quelle est la dernière version de l'application ? | C11: Version 14.8 | D11: Version 14.8 | E11: =IF(TRIM(B11)="","",IF(TRIM(C11)="",0,1)) -> 1 | F11: Non
B12: Etes-vous au courant d’une évolution majeure en cours sur cette Application ? | C12: Oui | D12: La version 14.7.0.0.0 d’Oracle FLEXCUBE Universal Banking propose plusieurs améliorations significatives. Voici un aperçu des principales mises à jour : Améliorations : Fonctionnalités Avancées : Intégration de nouvelles fonctionnalités pour améliorer l’efficacité opérationnelle des institutions financières. Amélioration des modules de gestion des comptes, des prêts et des transactions. ==> Interface Utilisateur :Interface utilisateur améliorée pour une meilleure expérience utilisateur. Simplification des processus de navigation et d’utilisation des différentes fonctionnalités du logiciel. ==>Sécurité :Renforcement des mesures de sécurité pour protéger les données sensibles. Mise en conformité avec les dernières réglementations en matière de sécurité bancaire. =>Détails sur les Composants Logiciels : ==>Composants Noyau :Mise à jour des composants noyau pour une performance optimisée. Améliorations dans les processus de traitement des transactions pour une rapidité accrue. ==>Modules Spécifiques :Améliorations dans les modules spécifiques tels que la gestion des risques, les services bancaires numériques et le traitement des paiements. Environnement et Logiciels Tiers : Compatibilité : Compatibilité étendue avec les derniers systèmes d'exploitation et infrastructures matérielles. Intégration facilitée avec les logiciels tiers couramment utilisés dans l’industrie bancaire. Outils de Développement : Inclusion de nouveaux outils de développement pour faciliter la personnalisation et l’extension des fonctionnalités du logiciel. Documentation enrichie pour aider les développeurs et les administrateurs à mieux comprendre et utiliser les nouvelles capacités. | E12: =IF(TRIM(B12)="","",IF(TRIM(C12)="",0,1)) -> 1 | F12: Non
B13: Qui contrôle les évolutions sur cette Application ? | C13: Oracle | D13: les évolutions de l'application Oracle FLEXCUBE Universal Banking sont le fruit d'un effort coordonné entre les équipes internes d'Oracle, les clients, et les partenaires externes, sous la direction et le contrôle principal de l'éditeur Oracle Corporation. | E13: =IF(TRIM(B13)="","",IF(TRIM(C13)="",0,1)) -> 1 | F13: Non
B14: Quelle est la criticité de cette application ? combien de temps peut-on supporter son indisponibilité (colonne détail) ? | C14: Primoridal | D14: Oracle FLEXCUBE Universal Banking a une criticité élevée, et la durée acceptable de son indisponibilité doit être très courte, idéalement limitée à quelques heures au maximum pour éviter des impacts significatifs sur les opérations bancaires et la satisfaction des clients | E14: =IF(TRIM(B14)="","",IF(TRIM(C14)="",0,1)) -> 1 | F14: Non
B15: Quels sont les modules utlisés? | C15: RB/CB/ PY /CL/ LN/ DE | D15: Voici quelques-uns des modules utilisés dans FCUBS : 1. Retail Banking (RB) : Gestion des opérations bancaires de détail, y compris les comptes d'épargne, les prêts personnels, etc. 2. Core Banking (CB) : Gère les fonctions bancaires de base telles que les comptes, les prêts, les dépôts, etc. 3. Payments (PY) : Gestion des opérations de paiement, y compris les virements, les paiements en temps réel, etc. 4. Collections (CL) : Gestion des opérations de recouvrement et de gestion des créances. 5. Lending (LN) : Gestion des opérations de prêt, y compris l'octroi de prêts, la gestion des garanties, etc. 6. Deposits (DE) : Gère les produits de dépôt. | E15: =IF(TRIM(B15)="","",IF(TRIM(C15)="",0,1)) -> 1 | F15: Non
B16: Est-ce que la solution dispose d'un module integré de gestion des documents (mise en page, formatage, impression, …) ? | C16: Non il fait l'objet d'une solution séparée | D16: Oracle FLEXCUBE Universal Banking (FCUBS) est un système de gestion bancaire complet, mais il n'inclut pas nativement de module intégré spécifique pour la gestion des documents tels que la mise en page, le formatage et l'impression. Cependant, FCUBS offre des capacités d'intégration avec d'autres systèmes et peut être personnalisé pour intégrer des solutions tierces qui fournissent ces fonctionnalités. Pour des besoins spécifiques , notre partenaire JMR Infotech a développer une solutions tierces spécialisées OAS. | E16: =IF(TRIM(B16)="","",IF(TRIM(C16)="",0,1)) -> 1 | F16: Non
